Workbook

Sheet Registo de operações
M2: Fundos iniciais | Q2: Mov. Add. Fundos | R2: Profit | S2: Current Funds | U2: Risk | V2: Total | Y2: Average | AC2: Comissões | AD2: Swaps | AE2: Capital liquido Gerado | AF2: Efective % (W. Add. Funds) | AG2: RRR Liquido Realizado
E3: Nº Op | F3: % Win | G3: Win | H3: Lose | I3: In | V3: Win | W3: Loss | X3: Total | Y3: Win | Z3: Loss | AA3: Total
E4: =COUNTA(U11:U211) -> 77 | F4: =G4/100%/(E4-I4) -> 0.38961039 | G4: =COUNTIF(M11:M211,"W") -> 30 | H4: =COUNTIF(M11:M211,"L") -> 47 | I4: =E4-G4-H4 -> 0 | M4: 5000 | Q4: 0 | R4: =SUM((X5)+(AD4)+(AC4)) -> 2430.7179 | S4: =SUM((M4)+(Q4)+(R4)) -> 7430.7179 | U4: 0.01 | V4: =Pontuação!B2 -> 0.86933381 | W4: =Pontuação!C2 -> -0.47 | X4: =SUM(Tabela2[[Ganhos %]:[Perdas %]]) -> 0.39933381 | Y4: =Pontuação!B3 -> 0.028977794 | Z4: =Pontuação!C3 -> -0.01 | AA4: =AVERAGE(Tabela2[[Ganhos %]:[Perdas %]]) -> 0.0051861534 | AC4: =SUM(AE11:AE211) -> 2.32 | AD4: =SUM(AF11:AF211) -> 86.37 | AE4: =SUM((V5)+(W5)+(AC4)+(AD4)) -> 2430.7179 | AF4: =SUM((AE4*100)/(M4+Q4))/100 -> 0.48614358 | AG4: =SUM(AK11:AK211) -> 0.41111098
V5: =Pontuação!D2 -> 5633.3383 | W5: =Pontuação!E2 -> -3291.3104 | X5: =SUM(Tabela2[[Ganhos €]:[Perdas €]]) -> 2342.0279 | Y5: =Pontuação!D3 -> 187.77794 | Z5: =Pontuação!E3 -> -70.02788 | AA5: =AVERAGE(Tabela2[[Ganhos €]:[Perdas €]]) -> 30.415947
B7: TIPO | C7: Nº T | D7: Nº S | E7: Dia da semana | F7: DATA | G7: Hora | H7: Grupo | I7: Par/Produto | J7: Estratégia | K7: Marco Temporal | L7: Tipo de entrada | M7: W L | N7: E | O7: G | P7: S | Q7: Starting Position | V7: Stop Loss | Y7: Take Profit | AC7: Close Position | AL7: Balanço de conta depois do trade
Q8: Account Funds (antes do trade) | R8: € Risk | S8: % Risk | T8: Lot | U8: Position entry | V8: Max Loss | W8: Pips | X8: € Loss | Y8: Take Profit | Z8: Pips | AA8: € Gain | AB8: RRR | AC8: Day Close | AD8: Closing price | AE8: Comissão | AF8: Swap | AG8: Lucro | AH8: Lucro liquido | AI8: Pips Close | AJ8: RRR Realizado | AK8: RRR Liquido | BH8: Currency | BI8: Grup | BJ8: Avaliação das Entradas:
A9: , | AR9: Sentido | AS9: Day W | AT9: Hora | AU9: Estrategia | AV9: Time Frame | AW9: W L | AX9: O C | AY9: News | AZ9: Candle | BA9: Grup | BB9: Emotional state
AR10: Short | AS10: 2ª F | AT10: Manhã | AU10: Retest | AV10: 1D | AW10: W | AX10: O | AY10: Yes | AZ10: Open | BA10: Majors | BB10: Impatience | BC10: x | BD10: 0 | BE10: 0 | BF10: -1 | BG10: x | BH10: EURUSD | BI10: =$BA$10 -> Majors
B11: Backtesting | C11: =C10+1 -> 1 | D11: 5 | E11: 2ª F | F11: 30 de Janeiro | G11: Tarde | I11: AUDNZD | J11: Breakout | K11: 3m | L11: short | M11: L | Q11: 5000 | R11: =IF(Q11="","",S11*Q11/100%) -> 50 | S11: 0.01 | T11: 0.01 | U11: 1.09209 | V11: 1.09317 | W11: =IF(V11="","",IF(L11="Long",U11-V11,V11-U11)) -> 0.00108 | X11: =IF(W11="","",R11) -> 50 | Y11: 1.0895 | Z11: =IF(Y11="","",IF(L11="Long",Y11-U11,U11-Y11)) -> 0.00259 | AA11: =IF(AB11="","",AB11*X11/1) -> 119.90741 | AB11: =IF(Z11="","",Z11*1/W11) -> 2.3981481 | AC11: 30 de Janeiro | AD11: 1.09317 | AE11: 0 | AF11: 0 | AG11: =-X11 -> -50 | AH11: =IF(AG11="","",AG11+AF11+AE11) -> -50 | AI11: =IF(AD11="","",IF(L11="Long",AD11-U11,U11-AD11)) -> -0.00108 | AJ11: =IF(AI11="","",AG11*S11/X11) -> -0.01 | AK11: =IF(AI11="","",(AG11+AF11+AE11)*S11/X11) -> -0.01 | AL11: =Q11+AG11 -> 4950 | AR11: Long | AS11: 3ª F | AT11: Tarde | AU11: Breakout | AV11: 12h | AW11: L | AX11: C | AY11: No | AZ11: Close | BA11: Minors | BB11: Fear | BD11: 0.1 | BE11: 0.1 | BF11: 0 | BH11: AUDUSD | BI11: =$BA$10 -> Majors | BL11: A | BM11: Boa entrada - Com estratégia - No timming Correto - Boa probabilidade
B12: Backtesting | C12: =C11+1 -> 2 | D12: 5 | E12: 2ª F | F12: 30 de Janeiro | G12: Tarde | I12: GBPUSD | J12: Breakout | K12: 1m | L12: long | M12: L | Q12: =AL11 -> 4950 | R12: =IF(Q12="","",S12*Q12/100%) -> 49.5 | S12: 0.01 | T12: 0.01 | U12: 1.24002 | V12: 1.23976 | W12: =IF(V12="","",IF(L12="Long",U12-V12,V12-U12)) -> 0.00026 | X12: =IF(W12="","",R12) -> 49.5 | Y12: 1.2408 | Z12: =IF(Y12="","",IF(L12="Long",Y12-U12,U12-Y12)) -> 0.00078 | AA12: =IF(AB12="","",AB12*X12/1) -> 148.5 | AB12: =IF(Z12="","",Z12*1/W12) -> 3 | AC12: 30 de Janeiro | AD12: 1.23976 | AE12: 0 | AF12: 0 | AG12: =-X12 -> -49.5 | AH12: =IF(AG12="","",AG12+AF12+AE12) -> -49.5 | AI12: =IF(AD12="","",IF(L12="Long",AD12-U12,U12-AD12)) -> -0.00026 | AJ12: =IF(AI12="","",AG12*S12/X12) -> -0.01 | AK12: =IF(AI12="","",(AG12+AF12+AE12)*S12/X12) -> -0.01 | AL12: =Q12+AG12 -> 4900.5 | AS12: 4ª F | AT12: Noite | AU12: Bandeira | AV12: 8h | AY12: n/a | AZ12: Next | BA12: Exotics | BB12: Greed | BD12: 0.2 | BE12: 0.2 | BF12: 1 | BH12: GBPCHF | BI12: =$BA$10 -> Majors | BL12: B | BM12: Boa entrada - Com alguma estratégia - Alguma Probabilidade
B13: Backtesting | C13: =C12+1 -> 3 | D13: 5 | E13: 2ª F | F13: 30 de Janeiro | G13: Tarde | I13: CADJPY | J13: Breakout | K13: 1m | L13: long | M13: W | Q13: =AL12 -> 4900.5 | R13: =IF(Q13="","",S13*Q13/100%) -> 49.005 | S13: 0.01 | T13: 0.02 | U13: 97.502 | V13: 97.445 | W13: =IF(V13="","",IF(L13="Long",U13-V13,V13-U13)) -> 0.057 | X13: =IF(W13="","",R13) -> 49.005 | Y13: 97.675 | Z13: =IF(Y13="","",IF(L13="Long",Y13-U13,U13-Y13)) -> 0.173 | AA13: =IF(AB13="","",AB13*X13/1) -> 148.73447 | AB13: =IF(Z13="","",Z13*1/W13) -> 3.0350877 | AC13: 30 de Janeiro | AD13: 97.675 | AE13: 0 | AF13: 0 | AG13: =+AA13 -> 148.73447 | AH13: =IF(AG13="","",AG13+AF13+AE13) -> 148.73447 | AI13: =IF(AD13="","",IF(L13="Long",AD13-U13,U13-AD13)) -> 0.173 | AJ13: =IF(AI13="","",AG13*S13/X13) -> 0.030350877 | AK13: =IF(AI13="","",(AG13+AF13+AE13)*S13/X13) -> 0.030350877 | AL13: =Q13+AG13 -> 5049.2345 | AS13: 5ª F | AU13: Continuation | AV13: 4h | AZ13: n/a | BA13: Indices | BB13: Hope | BD13: 0.3 | BE13: 0.3 | BF13: 2 | BH13: GBPUSD | BI13: =$BA$10 -> Majors | BL13: C | BM13: Razoavél - Com alguma estratégia - Mas impulsiva
B14: Testing em tempo real | C14: =C13+1 -> 4 | D14: 5 | E14: 3ª F | F14: 31 de janeiro | G14: Manhã | I14: GBPUSD | J14: Breakout | K14: 3m | L14: short | M14: W | Q14: =AL13 -> 5049.2345 | R14: =IF(Q14="","",S14*Q14/100%) -> 50.492345 | S14: 0.01 | T14: 0.5 | U14: 1.23495 | V14: 1.23657 | W14: =IF(V14="","",IF(L14="Long",U14-V14,V14-U14)) -> 0.00162 | X14: =IF(W14="","",R14) -> 50.492345 | Y14: 1.23006 | Z14: =IF(Y14="","",IF(L14="Long",Y14-U14,U14-Y14)) -> 0.00489 | AA14: =IF(AB14="","",AB14*X14/1) -> 152.41208 | AB14: =IF(Z14="","",Z14*1/W14) -> 3.0185185 | AC14: 31 de janeiro | AD14: 1.23006 | AE14: 0 | AF14: 0 | AG14: =+AA14 -> 152.41208 | AH14: =IF(AG14="","",AG14+AF14+AE14) -> 152.41208 | AI14: =IF(AD14="","",IF(L14="Long",AD14-U14,U14-AD14)) -> 0.00489 | AJ14: =IF(AI14="","",AG14*S14/X14) -> 0.030185185 | AK14: =IF(AI14="","",(AG14+AF14+AE14)*S14/X14) -> 0.030185185 | AL14: =Q14+AG14 -> 5201.6466 | AS14: 6ª F | AV14: 2h | BA14: Commod | BB14: Confidence | BD14: 0.4 | BE14: 0.4 | BF14: 3 | BH14: USDCAD | BI14: =$BA$10 -> Majors | BL14: D | BM14: Má entrada - Sem estratégia e impulsiva
B15: Testing em tempo real | C15: =C14+1 -> 5 | D15: 5 | E15: 5ª F | F15: 2 de Fevereiro | G15: Manhã | J15: Breakout | K15: 15m | L15: short | M15: W | Q15: =AL14 -> 5201.6466 | R15: =IF(Q15="","",S15*Q15/100%) -> 52.016466 | S15: 0.01 | T15: 0.01 | U15: 83.291 | V15: 83.559 | W15: =IF(V15="","",IF(L15="Long",U15-V15,V15-U15)) -> 0.268 | X15: =IF(W15="","",R15) -> 52.016466 | Y15: 82.488 | Z15: =IF(Y15="","",IF(L15="Long",Y15-U15,U15-Y15)) -> 0.803 | AA15: =IF(AB15="","",AB15*X15/1) -> 155.85531 | AB15: =IF(Z15="","",Z15*1/W15) -> 2.9962687 | AC15: 2 de Fevereiro | AD15: 82.488 | AE15: 0 | AF15: 0 | AG15: =+AA15 -> 155.85531 | AH15: =IF(AG15="","",AG15+AF15+AE15) -> 155.85531 | AI15: =IF(AD15="","",IF(L15="Long",AD15-U15,U15-AD15)) -> 0.803 | AJ15: =IF(AI15="","",AG15*S15/X15) -> 0.029962687 | AK15: =IF(AI15="","",(AG15+AF15+AE15)*S15/X15) -> 0.029962687 | AL15: =Q15+AG15 -> 5357.5019 | AV15: 1h | BB15: Uncertainty | BD15: 0.5 | BE15: 0.5 | BF15: 4 | BH15: USDCHF | BI15: =$BA$10 -> Majors
B16: Backtesting | C16: =C15+1 -> 6 | D16: 5 | E16: 6ª F | F16: 3 de Fevereiro | G16: Manhã | I16: EURUSD | J16: Breakout | K16: 1m | L16: long | M16: L | Q16: =AL15 -> 5357.5019 | R16: =IF(Q16="","",S16*Q16/100%) -> 53.575019 | S16: 0.01 | T16: 0.03 | U16: 1.08959 | V16: 1.08936 | W16: =IF(V16="","",IF(L16="Long",U16-V16,V16-U16)) -> 0.00023 | X16: =IF(W16="","",R16) -> 53.575019 | Y16: 1.09028 | Z16: =IF(Y16="","",IF(L16="Long",Y16-U16,U16-Y16)) -> 0.00069 | AA16: =IF(AB16="","",AB16*X16/1) -> 160.72506 | AB16: =IF(Z16="","",Z16*1/W16) -> 3 | AC16: 3 de Fevereiro | AD16: 1.08936 | AE16: 0 | AF16: 0 | AG16: =-X16 -> -53.575019 | AH16: =IF(AG16="","",AG16+AF16+AE16) -> -53.575019 | AI16: =IF(AD16="","",IF(L16="Long",AD16-U16,U16-AD16)) -> -0.00023 | AJ16: =IF(AI16="","",AG16*S16/X16) -> -0.01 | AK16: =IF(AI16="","",(AG16+AF16+AE16)*S16/X16) -> -0.01 | AL16: =Q16+AG16 -> 5303.9268 | AV16: 30m | BB16: Serene | BD16: 0.6 | BE16: 0.6 | BF16: 5 | BH16: USDJPY | BI16: =$BA$10 -> Majors | BJ16: Avaliação da Gestão
B17: Backtesting | C17: =C16+1 -> 7 | D17: 5 | E17: 6ª F | F17: 3 de Fevereiro | G17: Tarde | I17: AUDCHF | J17: Breakout | K17: 5m | L17: short | M17: W | Q17: =AL16 -> 5303.9268 | R17: =IF(Q17="","",S17*Q17/100%) -> 53.039268 | S17: 0.01 | T17: 0.01 | U17: 0.64558 | V17: 0.64653 | W17: =IF(V17="","",IF(L17="Long",U17-V17,V17-U17)) -> 0.00095 | X17: =IF(W17="","",R17) -> 53.039268 | Y17: 0.6427 | Z17: =IF(Y17="","",IF(L17="Long",Y17-U17,U17-Y17)) -> 0.00288 | AA17: =IF(AB17="","",AB17*X17/1) -> 160.79273 | AB17: =IF(Z17="","",Z17*1/W17) -> 3.0315789 | AC17: 3 de Fevereiro | AD17: 0.6427 | AE17: 0 | AF17: 0 | AG17: =+AA17 -> 160.79273 | AH17: =IF(AG17="","",AG17+AF17+AE17) -> 160.79273 | AI17: =IF(AD17="","",IF(L17="Long",AD17-U17,U17-AD17)) -> 0.00288 | AJ17: =IF(AI17="","",AG17*S17/X17) -> 0.030315789 | AK17: =IF(AI17="","",(AG17+AF17+AE17)*S17/X17) -> 0.030315789 | AL17: =Q17+AG17 -> 5464.7196 | AV17: 15m | BD17: 0.7 | BE17: 0.7 | BF17: 6 | BH17: AUDCAD | BI17: =$BA$11 -> Minors | BL17: A | BM17: Trailing Stop com a sequência de máximos e minimos - Confortável com a posição - Posição encaminhada
B18: Backtesting | C18: =C17+1 -> 8 | D18: 5 | E18: 6ª F | F18: 3 de Fevereiro | G18: Tarde | J18: Breakout | K18: 3m | L18: short | M18: L | Q18: =AL17 -> 5464.7196 | R18: =IF(Q18="","",S18*Q18/100%) -> 54.647196 | S18: 0.01 | T18: 0.05 | U18: 0.68277 | V18: 0.68325 | W18: =IF(V18="","",IF(L18="Long",U18-V18,V18-U18)) -> 0.00048 | X18: =IF(W18="","",R18) -> 54.647196 | Y18: 0.68161 | Z18: =IF(Y18="","",IF(L18="Long",Y18-U18,U18-Y18)) -> 0.00116 | AA18: =IF(AB18="","",AB18*X18/1) -> 132.06406 | AB18: =IF(Z18="","",Z18*1/W18) -> 2.4166667 | AC18: 3 de Fevereiro | AD18: 0.68325 | AE18: 0 | AF18: 0 | AG18: =-X18 -> -54.647196 | AH18: =IF(AG18="","",AG18+AF18+AE18) -> -54.647196 | AI18: =IF(AD18="","",IF(L18="Long",AD18-U18,U18-AD18)) -> -0.00048 | AJ18: =IF(AI18="","",AG18*S18/X18) -> -0.01 | AK18: =IF(AI18="","",(AG18+AF18+AE18)*S18/X18) -> -0.01 | AL18: =Q18+AG18 -> 5410.0724 | AV18: 5m | BD18: 0.8 | BE18: 0.8 | BF18: 7 | BH18: AUDCHF | BI18: =$BA$11 -> Minors | BL18: B | BM18: Trailing Stop com a sequência de máximos e minimos - Preocupação com a posição - Posição a perder estrutura
B19: Backtesting | C19: =C18+1 -> 9 | D19: 5 | E19: 6ª F | F19: 3 de Fevereiro | G19: Tarde | I19: EURAUD | J19: Breakout | K19: 3m | L19: long | M19: W | Q19: =AL18 -> 5410.0724 | R19: =IF(Q19="","",S19*Q19/100%) -> 54.100724 | S19: 0.01 | T19: 0.03 | U19: 1.54298 | V19: 1.54138 | W19: =IF(V19="","",IF(L19="Long",U19-V19,V19-U19)) -> 0.0016 | X19: =IF(W19="","",R19) -> 54.100724 | Y19: 1.54783 | Z19: =IF(Y19="","",IF(L19="Long",Y19-U19,U19-Y19)) -> 0.00485 | AA19: =IF(AB19="","",AB19*X19/1) -> 163.99282 | AB19: =IF(Z19="","",Z19*1/W19) -> 3.03125 | AC19: 3 de Fevereiro | AD19: 1.54783 | AE19: 0 | AF19: 0 | AG19: =+AA19 -> 163.99282 | AH19: =IF(AG19="","",AG19+AF19+AE19) -> 163.99282 | AI19: =IF(AD19="","",IF(L19="Long",AD19-U19,U19-AD19)) -> 0.00485 | AJ19: =IF(AI19="","",AG19*S19/X19) -> 0.0303125 | AK19: =IF(AI19="","",(AG19+AF19+AE19)*S19/X19) -> 0.0303125 | AL19: =Q19+AG19 -> 5574.0652 | AV19: 3m | BD19: 0.9 | BE19: 0.9 | BF19: 8 | BH19: AUDJPY | BI19: =$BA$11 -> Minors | BL19: C | BM19: Alteração do stop sem estratégia de máximos e minimos - Preocupação com a posição
B20: Testing em tempo real | C20: =C19+1 -> 10 | D20: 6 | E20: 2ª F | F20: 6 de Fevereiro | G20: Manhã | I20: AUDUSD | J20: Breakout | K20: 5m | L20: short | M20: W | Q20: =AL19 -> 5574.0652 | R20: =IF(Q20="","",S20*Q20/100%) -> 55.740652 | S20: 0.01 | T20: 0.05 | U20: 0.69251 | V20: 0.69434 | W20: =IF(V20="","",IF(L20="Long",U20-V20,V20-U20)) -> 0.00183 | X20: =IF(W20="","",R20) -> 55.740652 | Y20: 0.68799 | Z20: =IF(Y20="","",IF(L20="Long",Y20-U20,U20-Y20)) -> 0.00452 | AA20: =IF(AB20="","",AB20*X20/1) -> 137.67636 | AB20: =IF(Z20="","",Z20*1/W20) -> 2.4699454 | AC20: 6 de Fevereiro | AD20: 0.68799 | AE20: 0 | AF20: 0 | AG20: =+AA20 -> 137.67636 | AH20: =IF(AG20="","",AG20+AF20+AE20) -> 137.67636 | AI20: =IF(AD20="","",IF(L20="Long",AD20-U20,U20-AD20)) -> 0.00452 | AJ20: =IF(AI20="","",AG20*S20/X20) -> 0.024699454 | AK20: =IF(AI20="","",(AG20+AF20+AE20)*S20/X20) -> 0.024699454 | AL20: =Q20+AG20 -> 5711.7416 | AV20: 1S | BD20: 1 | BE20: 1 | BH20: AUDNZD | BI20: =$BA$11 -> Minors | BL20: D | BM20: Sem Gestão - Não Fechei após a 1ª/2ª vela negativa
B21: Backtesting | C21: =C20+1 -> 11 | D21: 6 | E21: 4ª F | F21: 8 de Fevereiro | G21: Noite | I21: USDSGD | J21: Breakout | K21: 5m | L21: long | M21: L | Q21: =AL20 -> 5711.7416 | R21: =IF(Q21="","",S21*Q21/100%) -> 57.117416 | S21: 0.01 | T21: 0.01 | U21: 1.32401 | V21: 1.32323 | W21: =IF(V21="","",IF(L21="Long",U21-V21,V21-U21)) -> 0.00078 | X21: =IF(W21="","",R21) -> 57.117416 | Y21: 1.32635 | Z21: =IF(Y21="","",IF(L21="Long",Y21-U21,U21-Y21)) -> 0.00234 | AA21: =IF(AB21="","",AB21*X21/1) -> 171.35225 | AB21: =IF(Z21="","",Z21*1/W21) -> 3 | AC21: 8 de Fevereiro | AD21: 1.32323 | AE21: 0 | AF21: 0 | AG21: =-X21 -> -57.117416 | AH21: =IF(AG21="","",AG21+AF21+AE21) -> -57.117416 | AI21: =IF(AD21="","",IF(L21="Long",AD21-U21,U21-AD21)) -> -0.00078 | AJ21: =IF(AI21="","",AG21*S21/X21) -> -0.01 | AK21: =IF(AI21="","",(AG21+AF21+AE21)*S21/X21) -> -0.01 | AL21: =Q21+AG21 -> 5654.6241 | AV21: 6h | BH21: CADCHF | BI21: =$BA$11 -> Minors
B22: Backtesting | C22: =C21+1 -> 12 | D22: 6 | E22: 4ª F | F22: 8 de Fevereiro | G22: Noite | I22: USDJPY | J22: Breakout | K22: 5m | L22: long | M22: L | Q22: =AL21 -> 5654.6241 | R22: =IF(Q22="","",S22*Q22/100%) -> 56.546241 | S22: 0.01 | T22: 0.22 | U22: 131.99 | V22: 131.596 | W22: =IF(V22="","",IF(L22="Long",U22-V22,V22-U22)) -> 0.394 | X22: =IF(W22="","",R22) -> 56.546241 | Y22: 133.5 | Z22: =IF(Y22="","",IF(L22="Long",Y22-U22,U22-Y22)) -> 1.51 | AA22: =IF(AB22="","",AB22*X22/1) -> 216.71275 | AB22: =IF(Z22="","",Z22*1/W22) -> 3.8324873 | AC22: 8 de Fevereiro | AD22: 131.596 | AE22: 0 | AF22: 0 | AG22: =-X22 -> -56.546241 | AH22: =IF(AG22="","",AG22+AF22+AE22) -> -56.546241 | AI22: =IF(AD22="","",IF(L22="Long",AD22-U22,U22-AD22)) -> -0.394 | AJ22: =IF(AI22="","",AG22*S22/X22) -> -0.01 | AK22: =IF(AI22="","",(AG22+AF22+AE22)*S22/X22) -> -0.01 | AL22: =Q22+AG22 -> 5598.0779 | AV22: 15s | BH22: CADJPY | BI22: =$BA$11 -> Minors | BJ22: Avaliação da Saída
B23: Backtesting | C23: =C22+1 -> 13 | D23: 7 | E23: 4ª F | F23: 15 de Fevereiro | G23: Manhã | J23: Breakout | K23: 1m | L23: short | M23: W | Q23: =AL22 -> 5598.0779 | R23: =IF(Q23="","",S23*Q23/100%) -> 55.980779 | S23: 0.01 | T23: 0.02 | U23: 0.69301 | V23: 0.69346 | W23: =IF(V23="","",IF(L23="Long",U23-V23,V23-U23)) -> 0.00045 | X23: =IF(W23="","",R23) -> 55.980779 | Y23: 0.69166 | Z23: =IF(Y23="","",IF(L23="Long",Y23-U23,U23-Y23)) -> 0.00135 | AA23: =IF(AB23="","",AB23*X23/1) -> 167.94234 | AB23: =IF(Z23="","",Z23*1/W23) -> 3 | AC23: 15 de Fevereiro | AD23: 0.69166 | AE23: 0 | AF23: 0 | AG23: =+AA23 -> 167.94234 | AH23: =IF(AG23="","",AG23+AF23+AE23) -> 167.94234 | AI23: =IF(AD23="","",IF(L23="Long",AD23-U23,U23-AD23)) -> 0.00135 | AJ23: =IF(AI23="","",AG23*S23/X23) -> 0.03 | AK23: =IF(AI23="","",(AG23+AF23+AE23)*S23/X23) -> 0.03 | AL23: =Q23+AG23 -> 5766.0202 | AV23: 1m | BH23: CHFJPY | BI23: =$BA$11 -> Minors | BL23: A | BM23: Take Profit no ponto definido inicialmente - saida automática
B24: Testing em tempo real | C24: =C23+1 -> 14 | D24: 7 | E24: 5ª F | F24: 16 de Fevereiro | G24: Manhã | I24: USDCAD | J24: Breakout | K24: 5m | L24: short | M24: W | Q24: =AL23 -> 5766.0202 | R24: =IF(Q24="","",S24*Q24/100%) -> 57.660202 | S24: 0.01 | T24: 0.07 | U24: 1.33704 | V24: 1.33808 | W24: =IF(V24="","",IF(L24="Long",U24-V24,V24-U24)) -> 0.00104 | X24: =IF(W24="","",R24) -> 57.660202 | Y24: 1.33359 | Z24: =IF(Y24="","",IF(L24="Long",Y24-U24,U24-Y24)) -> 0.00345 | AA24: =IF(AB24="","",AB24*X24/1) -> 191.27663 | AB24: =IF(Z24="","",Z24*1/W24) -> 3.3173077 | AC24: 16 de Fevereiro | AD24: 1.33359 | AE24: 0 | AF24: 0 | AG24: =+AA24 -> 191.27663 | AH24: =IF(AG24="","",AG24+AF24+AE24) -> 191.27663 | AI24: =IF(AD24="","",IF(L24="Long",AD24-U24,U24-AD24)) -> 0.00345 | AJ24: =IF(AI24="","",AG24*S24/X24) -> 0.033173077 | AK24: =IF(AI24="","",(AG24+AF24+AE24)*S24/X24) -> 0.033173077 | AL24: =Q24+AG24 -> 5957.2969 | BH24: EURAUD | BI24: =$BA$11 -> Minors | BL24: B | BM24: Stop-Win em trailing Sop com estratégia
B25: Backtesting | C25: =C24+1 -> 15 | D25: 7 | E25: 5ª F | F25: 16 de Fevereiro | G25: Manhã | I25: GBPJPY | J25: Breakout | K25: 1m | L25: long | M25: L | Q25: =AL24 -> 5957.2969 | R25: =IF(Q25="","",S25*Q25/100%) -> 59.572969 | S25: 0.01 | T25: 0.02 | U25: 159.393 | V25: 159.297 | W25: =IF(V25="","",IF(L25="Long",U25-V25,V25-U25)) -> 0.096 | X25: =IF(W25="","",R25) -> 59.572969 | Y25: 159.682 | Z25: =IF(Y25="","",IF(L25="Long",Y25-U25,U25-Y25)) -> 0.289 | AA25: =IF(AB25="","",AB25*X25/1) -> 179.33946 | AB25: =IF(Z25="","",Z25*1/W25) -> 3.0104167 | AC25: 16 de Fevereiro | AD25: 159.297 | AE25: 0 | AF25: 0 | AG25: =-X25 -> -59.572969 | AH25: =IF(AG25="","",AG25+AF25+AE25) -> -59.572969 | AI25: =IF(AD25="","",IF(L25="Long",AD25-U25,U25-AD25)) -> -0.096 | AJ25: =IF(AI25="","",AG25*S25/X25) -> -0.01 | AK25: =IF(AI25="","",(AG25+AF25+AE25)*S25/X25) -> -0.01 | AL25: =Q25+AG25 -> 5897.7239 | BH25: EURCAD | BI25: =$BA$11 -> Minors | BL25: C | BM25: Stop-Loss Parcial devido a falha na posição - Reversão da posição a negativo - Stop de Segurança
B26: Backtesting | C26: =C25+1 -> 16 | D26: 7 | E26: 5ª F | F26: 16 de Fevereiro | G26: Manhã | I26: GBPUSD | J26: Breakout | K26: 1m | L26: long | M26: W | Q26: =AL25 -> 5897.7239 | R26: =IF(Q26="","",S26*Q26/100%) -> 58.977239 | S26: 0.01 | T26: 0.25 | U26: 1.21938 | V26: 1.21872 | W26: =IF(V26="","",IF(L26="Long",U26-V26,V26-U26)) -> 0.00066 | X26: =IF(W26="","",R26) -> 58.977239 | Y26: 1.22136 | Z26: =IF(Y26="","",IF(L26="Long",Y26-U26,U26-Y26)) -> 0.00198 | AA26: =IF(AB26="","",AB26*X26/1) -> 176.93172 | AB26: =IF(Z26="","",Z26*1/W26) -> 3 | AC26: 16 de Fevereiro | AD26: 1.22 | AE26: 0 | AF26: 0 | AG26: =+AA26 -> 176.93172 | AH26: =IF(AG26="","",AG26+AF26+AE26) -> 176.93172 | AI26: =IF(AD26="","",IF(L26="Long",AD26-U26,U26-AD26)) -> 0.00062 | AJ26: =IF(AI26="","",AG26*S26/X26) -> 0.03 | AK26: =IF(AI26="","",(AG26+AF26+AE26)*S26/X26) -> 0.03 | AL26: =Q26+AG26 -> 6074.6556 | BH26: EURCHF | BI26: =$BA$11 -> Minors | BL26: D | BM26: Stop-Loss Total - Má gestão de saída da posição
B27: Backtesting | C27: =C26+1 -> 17 | D27: 7 | E27: 5ª F | F27: 16 de Fevereiro | G27: Manhã | I27: EURJPY | J27: Breakout | K27: 5m | L27: long | M27: W | Q27: =AL26 -> 6074.6556 | R27: =IF(Q27="","",S27*Q27/100%) -> 60.746556 | S27: 0.01 | T27: 0.01 | U27: 141.852 | V27: 141.551 | W27: =IF(V27="","",IF(L27="Long",U27-V27,V27-U27)) -> 0.301 | X27: =IF(W27="","",R27) -> 60.746556 | Y27: 142.755 | Z27: =IF(Y27="","",IF(L27="Long",Y27-U27,U27-Y27)) -> 0.903 | AA27: =IF(AB27="","",AB27*X27/1) -> 182.23967 | AB27: =IF(Z27="","",Z27*1/W27) -> 3 | AC27: 16 de Fevereiro | AD27: 142.755 | AE27: 0 | AF27: 0 | AG27: =+AA27 -> 182.23967 | AH27: =IF(AG27="","",AG27+AF27+AE27) -> 182.23967 | AI27: =IF(AD27="","",IF(L27="Long",AD27-U27,U27-AD27)) -> 0.903 | AJ27: =IF(AI27="","",AG27*S27/X27) -> 0.03 | AK27: =IF(AI27="","",(AG27+AF27+AE27)*S27/X27) -> 0.03 | AL27: =Q27+AG27 -> 6256.8953 | BH27: EURGBP | BI27: =$BA$11 -> Minors | BL27: E | BM27: Fecho Manual - Desconforto com a posição/ 1ª Vela negativa / Reversão
B28: Backtesting | C28: =C27+1 -> 18 | D28: 7 | E28: 5ª F | F28: 16 de Fevereiro | G28: Tarde | I28: CADJPY | J28: Breakout | K28: 5m | L28: long | M28: W | Q28: =AL27 -> 6256.8953 | R28: =IF(Q28="","",S28*Q28/100%) -> 62.568953 | S28: 0.01 | T28: 0.01 | U28: 99.574 | V28: 99.486 | W28: =IF(V28="","",IF(L28="Long",U28-V28,V28-U28)) -> 0.088 | X28: =IF(W28="","",R28) -> 62.568953 | Y28: 99.838 | Z28: =IF(Y28="","",IF(L28="Long",Y28-U28,U28-Y28)) -> 0.264 | AA28: =IF(AB28="","",AB28*X28/1) -> 187.70686 | AB28: =IF(Z28="","",Z28*1/W28) -> 3 | AC28: 16 de Fevereiro | AD28: 99.838 | AE28: 0 | AF28: 0 | AG28: =+AA28 -> 187.70686 | AH28: =IF(AG28="","",AG28+AF28+AE28) -> 187.70686 | AI28: =IF(AD28="","",IF(L28="Long",AD28-U28,U28-AD28)) -> 0.264 | AJ28: =IF(AI28="","",AG28*S28/X28) -> 0.03 | AK28: =IF(AI28="","",(AG28+AF28+AE28)*S28/X28) -> 0.03 | AL28: =Q28+AG28 -> 6444.6021 | BH28: EURJPY | BI28: =$BA$11 -> Minors
B29: Backtesting | C29: =C28+1 -> 19 | D29: 7 | E29: 5ª F | F29: 16 de Fevereiro | G29: Tarde | I29: AUDCAD | J29: Breakout | K29: 1m | L29: short | M29: W | Q29: =AL28 -> 6444.6021 | R29: =IF(Q29="","",S29*Q29/100%) -> 64.446021 | S29: 0.01 | T29: 1 | U29: 0.92624 | V29: 0.92675 | W29: =IF(V29="","",IF(L29="Long",U29-V29,V29-U29)) -> 0.00051 | X29: =IF(W29="","",R29) -> 64.446021 | Y29: 0.92471 | Z29: =IF(Y29="","",IF(L29="Long",Y29-U29,U29-Y29)) -> 0.00153 | AA29: =IF(AB29="","",AB29*X29/1) -> 193.33806 | AB29: =IF(Z29="","",Z29*1/W29) -> 3 | AC29: 16 de Fevereiro | AD29: 0.92471 | AE29: 0 | AF29: 0 | AG29: =+AA29 -> 193.33806 | AH29: =IF(AG29="","",AG29+AF29+AE29) -> 193.33806 | AI29: =IF(AD29="","",IF(L29="Long",AD29-U29,U29-AD29)) -> 0.00153 | AJ29: =IF(AI29="","",AG29*S29/X29) -> 0.03 | AK29: =IF(AI29="","",(AG29+AF29+AE29)*S29/X29) -> 0.03 | AL29: =Q29+AG29 -> 6637.9402 | BH29: EURNZD | BI29: =$BA$11 -> Minors
B30: Backtesting | C30: =C29+1 -> 20 | D30: 7 | E30: 5ª F | F30: 16 de Fevereiro | G30: Noite | I30: GBPJPY | J30: Breakout | K30: 1m | L30: long | M30: L | Q30: =AL29 -> 6637.9402 | R30: =IF(Q30="","",S30*Q30/100%) -> 66.379402 | S30: 0.01 | T30: 0.01 | U30: 161.744 | V30: 161.625 | W30: =IF(V30="","",IF(L30="Long",U30-V30,V30-U30)) -> 0.119 | X30: =IF(W30="","",R30) -> 66.379402 | Y30: 162.106 | Z30: =IF(Y30="","",IF(L30="Long",Y30-U30,U30-Y30)) -> 0.362 | AA30: =IF(AB30="","",AB30*X30/1) -> 201.92726 | AB30: =IF(Z30="","",Z30*1/W30) -> 3.0420168 | AC30: 16 de Fevereiro | AD30: 161.625 | AE30: 0 | AF30: 0 | AG30: =-X30 -> -66.379402 | AH30: =IF(AG30="","",AG30+AF30+AE30) -> -66.379402 | AI30: =IF(AD30="","",IF(L30="Long",AD30-U30,U30-AD30)) -> -0.119 | AJ30: =IF(AI30="","",AG30*S30/X30) -> -0.01 | AK30: =IF(AI30="","",(AG30+AF30+AE30)*S30/X30) -> -0.01 | AL30: =Q30+AG30 -> 6571.5608 | BH30: GBPAUD | BI30: =$BA$11 -> Minors
B31: Backtesting | C31: =C30+1 -> 21 | D31: 7 | E31: 6ª F | F31: 17 de Fevereiro | G31: Manhã | I31: CADJPY | J31: Breakout | K31: 1m | L31: long | M31: L | Q31: =AL30 -> 6571.5608 | R31: =IF(Q31="","",S31*Q31/100%) -> 65.715608 | S31: 0.01 | T31: 0.01 | U31: 100.064 | V31: 100.005 | W31: =IF(V31="","",IF(L31="Long",U31-V31,V31-U31)) -> 0.059 | X31: =IF(W31="","",R31) -> 65.715608 | Y31: 100.236 | Z31: =IF(Y31="","",IF(L31="Long",Y31-U31,U31-Y31)) -> 0.172 | AA31: =IF(AB31="","",AB31*X31/1) -> 191.5777 | AB31: =IF(Z31="","",Z31*1/W31) -> 2.9152542 | AC31: 17 de Fevereiro | AD31: 100.005 | AE31: 0 | AF31: 0 | AG31: =-X31 -> -65.715608 | AH31: =IF(AG31="","",AG31+AF31+AE31) -> -65.715608 | AI31: =IF(AD31="","",IF(L31="Long",AD31-U31,U31-AD31)) -> -0.059 | AJ31: =IF(AI31="","",AG31*S31/X31) -> -0.01 | AK31: =IF(AI31="","",(AG31+AF31+AE31)*S31/X31) -> -0.01 | AL31: =Q31+AG31 -> 6505.8452 | BH31: GBPCAD | BI31: =$BA$11 -> Minors
B32: Backtesting | C32: =C31+1 -> 22 | D32: 7 | E32: 6ª F | F32: 17 de Fevereiro | G32: Manhã | I32: AUDJPY | J32: Breakout | K32: 3m | L32: long | M32: L | Q32: =AL31 -> 6505.8452 | R32: =IF(Q32="","",S32*Q32/100%) -> 65.058452 | S32: 0.01 | T32: 0.11 | U32: 92.601 | V32: 92.482 | W32: =IF(V32="","",IF(L32="Long",U32-V32,V32-U32)) -> 0.119 | X32: =IF(W32="","",R32) -> 65.058452 | Y32: 92.959 | Z32: =IF(Y32="","",IF(L32="Long",Y32-U32,U32-Y32)) -> 0.358 | AA32: =IF(AB32="","",AB32*X32/1) -> 195.72207 | AB32: =IF(Z32="","",Z32*1/W32) -> 3.0084034 | AC32: 17 de Fevereiro | AD32: 92.482 | AE32: 0 | AF32: 0 | AG32: =-X32 -> -65.058452 | AH32: =IF(AG32="","",AG32+AF32+AE32) -> -65.058452 | AI32: =IF(AD32="","",IF(L32="Long",AD32-U32,U32-AD32)) -> -0.119 | AJ32: =IF(AI32="","",AG32*S32/X32) -> -0.01 | AK32: =IF(AI32="","",(AG32+AF32+AE32)*S32/X32) -> -0.01 | AL32: =Q32+AG32 -> 6440.7867 | BH32: GBPCHF | BI32: =$BA$11 -> Minors
B33: Backtesting | C33: =C32+1 -> 23 | D33: 13 | E33: 6ª F | F33: 31 de Março | G33: Manhã | I33: NZDUSD | J33: Breakout | K33: 3m | L33: long | M33: L | Q33: =AL32 -> 6440.7867 | R33: =IF(Q33="","",S33*Q33/100%) -> 64.407867 | S33: 0.01 | T33: 0.05 | U33: 0.62869 | V33: 0.62816 | W33: =IF(V33="","",IF(L33="Long",U33-V33,V33-U33)) -> 0.00053 | X33: =IF(W33="","",R33) -> 64.407867 | Y33: 0.63023 | Z33: =IF(Y33="","",IF(L33="Long",Y33-U33,U33-Y33)) -> 0.00154 | AA33: =IF(AB33="","",AB33*X33/1) -> 187.14739 | AB33: =IF(Z33="","",Z33*1/W33) -> 2.9056604 | AC33: 31 de Março | AD33: 0.62816 | AE33: 0 | AF33: 0 | AG33: =-X33 -> -64.407867 | AH33: =IF(AG33="","",AG33+AF33+AE33) -> -64.407867 | AI33: =IF(AD33="","",IF(L33="Long",AD33-U33,U33-AD33)) -> -0.00053 | AJ33: =IF(AI33="","",AG33*S33/X33) -> -0.01 | AK33: =IF(AI33="","",(AG33+AF33+AE33)*S33/X33) -> -0.01 | AL33: =Q33+AG33 -> 6376.3789 | BH33: GBPJPY | BI33: =$BA$11 -> Minors
B34: Testing em tempo real | C34: 24 | D34: 15 | E34: 3ª F | F34: 11 de Abril | G34: Tarde | H34: Majors | I34: USDJPY | J34: Breakout | K34: 1m | L34: long | M34: W | Q34: =AL33 -> 6376.3789 | R34: =IF(Q34="","",S34*Q34/100%) -> 63.763789 | S34: 0.01 | T34: 0.01 | U34: 133.211 | V34: 133.107 | W34: =IF(V34="","",IF(L34="Long",U34-V34,V34-U34)) -> 0.104 | X34: =IF(W34="","",R34) -> 63.763789 | Y34: 133.523 | Z34: =IF(Y34="","",IF(L34="Long",Y34-U34,U34-Y34)) -> 0.312 | AA34: =IF(AB34="","",AB34*X34/1) -> 191.29137 | AB34: =IF(Z34="","",Z34*1/W34) -> 3 | AC34: 11 de Abril | AD34: 133.523 | AE34: 0 | AF34: 0 | AG34: =+AA34 -> 191.29137 | AH34: =IF(AG34="","",AG34+AF34+AE34) -> 191.29137 | AI34: =IF(AD34="","",IF(L34="Long",AD34-U34,U34-AD34)) -> 0.312 | AJ34: =IF(AI34="","",AG34*S34/X34) -> 0.03 | AK34: =IF(AI34="","",(AG34+AF34+AE34)*S34/X34) -> 0.03 | AL34: =Q34+AG34 -> 6567.6702 | BH34: GBPNZD | BI34: =$BA$11 -> Minors
B35: Testing em tempo real | C35: 25 | D35: 15 | E35: 4ª F | F35: 12 de Abril | G35: Tarde | H35: Majors | I35: EURUSD | J35: Breakout | K35: 3m | L35: long | M35: L | Q35: =AL34 -> 6567.6702 | R35: =IF(Q35="","",S35*Q35/100%) -> 65.676702 | S35: 0.01 | T35: 0.01 | U35: 1.09274 | V35: 1.09201 | W35: =IF(V35="","",IF(L35="Long",U35-V35,V35-U35)) -> 0.00073 | X35: =IF(W35="","",R35) -> 65.676702 | Y35: 1.09493 | Z35: =IF(Y35="","",IF(L35="Long",Y35-U35,U35-Y35)) -> 0.00219 | AA35: =IF(AB35="","",AB35*X35/1) -> 197.03011 | AB35: =IF(Z35="","",Z35*1/W35) -> 3 | AC35: 12 de Abril | AD35: 1.09201 | AE35: 0 | AF35: 0 | AG35: =-X35 -> -65.676702 | AH35: =IF(AG35="","",AG35+AF35+AE35) -> -65.676702 | AI35: =IF(AD35="","",IF(L35="Long",AD35-U35,U35-AD35)) -> -0.00073 | AJ35: =IF(AI35="","",AG35*S35/X35) -> -0.01 | AK35: =IF(AI35="","",(AG35+AF35+AE35)*S35/X35) -> -0.01 | AL35: =Q35+AG35 -> 6501.9935 | BH35: NZDCAD | BI35: =$BA$11 -> Minors
B36: Testing em tempo real | C36: 26 | D36: 15 | E36: 4ª F | F36: 12 de Abril | G36: Tarde | H36: Majors | I36: GBPUSD | J36: Breakout | K36: 1m | L36: long | M36: W | Q36: =AL35 -> 6501.9935 | R36: =IF(Q36="","",S36*Q36/100%) -> 65.019935 | S36: 0.01 | T36: 0.01 | U36: 1.24715 | V36: 1.24616 | W36: =IF(V36="","",IF(L36="Long",U36-V36,V36-U36)) -> 0.00099 | X36: =IF(W36="","",R36) -> 65.019935 | Y36: 1.25012 | Z36: =IF(Y36="","",IF(L36="Long",Y36-U36,U36-Y36)) -> 0.00297 | AA36: =IF(AB36="","",AB36*X36/1) -> 195.05981 | AB36: =IF(Z36="","",Z36*1/W36) -> 3 | AC36: 12 de Abril | AD36: 1.25012 | AE36: 0 | AF36: 0 | AG36: =+AA36 -> 195.05981 | AH36: =IF(AG36="","",AG36+AF36+AE36) -> 195.05981 | AI36: =IF(AD36="","",IF(L36="Long",AD36-U36,U36-AD36)) -> 0.00297 | AJ36: =IF(AI36="","",AG36*S36/X36) -> 0.03 | AK36: =IF(AI36="","",(AG36+AF36+AE36)*S36/X36) -> 0.03 | AL36: =Q36+AG36 -> 6697.0533 | BH36: NZDCHF | BI36: =$BA$11 -> Minors
B37: Testing em tempo real | C37: 27 | D37: 15 | E37: 5ª F | F37: 13 de Abril | G37: Manhã | H37: Majors | I37: GBPUSD | J37: Breakout | K37: 1m | L37: long | M37: W | Q37: =AL36 -> 6697.0533 | R37: =IF(Q37="","",S37*Q37/100%) -> 66.970533 | S37: 0.01 | T37: 0.09 | U37: 1.25031 | V37: 1.24949 | W37: =IF(V37="","",IF(L37="Long",U37-V37,V37-U37)) -> 0.00082 | X37: =IF(W37="","",R37) -> 66.970533 | Y37: 1.25277 | Z37: =IF(Y37="","",IF(L37="Long",Y37-U37,U37-Y37)) -> 0.00246 | AA37: =IF(AB37="","",AB37*X37/1) -> 200.9116 | AB37: =IF(Z37="","",Z37*1/W37) -> 3 | AC37: 13 de Abril | AD37: 1.25277 | AE37: 0 | AF37: 0 | AG37: =+AA37 -> 200.9116 | AH37: =IF(AG37="","",AG37+AF37+AE37) -> 200.9116 | AI37: =IF(AD37="","",IF(L37="Long",AD37-U37,U37-AD37)) -> 0.00246 | AJ37: =IF(AI37="","",AG37*S37/X37) -> 0.03 | AK37: =IF(AI37="","",(AG37+AF37+AE37)*S37/X37) -> 0.03 | AL37: =Q37+AG37 -> 6897.9649 | BH37: NZDJPY | BI37: =$BA$11 -> Minors
B38: Testing em tempo real | C38: 28 | D38: 16 | E38: 3ª F | F38: 18 de Abril | G38: Manhã | H38: Majors | I38: GBPUSD | J38: Breakout | K38: 15s | L38: long | M38: L | Q38: =AL37 -> 6897.9649 | R38: =IF(Q38="","",S38*Q38/100%) -> 68.979649 | S38: 0.01 | T38: 0.01 | U38: 1.24214 | V38: 1.24161 | W38: =IF(V38="","",IF(L38="Long",U38-V38,V38-U38)) -> 0.00053 | X38: =IF(W38="","",R38) -> 68.979649 | Y38: 1.24373 | Z38: =IF(Y38="","",IF(L38="Long",Y38-U38,U38-Y38)) -> 0.00159 | AA38: =IF(AB38="","",AB38*X38/1) -> 206.93895 | AB38: =IF(Z38="","",Z38*1/W38) -> 3 | AC38: 18 de Abril | AD38: 1.24161 | AE38: 0 | AF38: 0 | AG38: =-X38 -> -68.979649 | AH38: =IF(AG38="","",AG38+AF38+AE38) -> -68.979649 | AI38: =IF(AD38="","",IF(L38="Long",AD38-U38,U38-AD38)) -> -0.00053 | AJ38: =IF(AI38="","",AG38*S38/X38) -> -0.01 | AK38: =IF(AI38="","",(AG38+AF38+AE38)*S38/X38) -> -0.01 | AL38: =Q38+AG38 -> 6828.9853 | BH38: NZDUSD | BI38: =$BA$11 -> Minors
B39: Backtesting | C39: 29 | D39: 17 | E39: 6ª F | F39: 28 de Abril | G39: Noite | H39: Majors | I39: AUDUSD | J39: Breakout | K39: 15s | L39: short | M39: W | Q39: =AL38 -> 6828.9853 | R39: =IF(Q39="","",S39*Q39/100%) -> 68.289853 | S39: 0.01 | T39: 0.02 | U39: 0.66089 | V39: 0.66135 | W39: =IF(V39="","",IF(L39="Long",U39-V39,V39-U39)) -> 0.00046 | X39: =IF(W39="","",R39) -> 68.289853 | Y39: 0.65951 | Z39: =IF(Y39="","",IF(L39="Long",Y39-U39,U39-Y39)) -> 0.00138 | AA39: =IF(AB39="","",AB39*X39/1) -> 204.86956 | AB39: =IF(Z39="","",Z39*1/W39) -> 3 | AC39: 28 de Abril | AD39: 0.65951 | AE39: 0 | AF39: 0 | AG39: =+AA39 -> 204.86956 | AH39: =IF(AG39="","",AG39+AF39+AE39) -> 204.86956 | AI39: =IF(AD39="","",IF(L39="Long",AD39-U39,U39-AD39)) -> 0.00138 | AJ39: =IF(AI39="","",AG39*S39/X39) -> 0.03 | AK39: =IF(AI39="","",(AG39+AF39+AE39)*S39/X39) -> 0.03 | AL39: =Q39+AG39 -> 7033.8549 | BH39: USDSGD | BI39: =$BA$11 -> Minors
B40: Testing em tempo real | C40: 30 | D40: 18 | E40: 4ª F | F40: 3 de Mario | G40: Manhã | H40: Majors | I40: USDCAD | J40: Breakout | K40: 1m | L40: long | M40: L | Q40: =AL39 -> 7033.8549 | R40: =IF(Q40="","",S40*Q40/100%) -> 70.338549 | S40: 0.01 | T40: 0.07 | U40: 1.36226 | V40: 1.3619 | W40: =IF(V40="","",IF(L40="Long",U40-V40,V40-U40)) -> 0.00036 | X40: =IF(W40="","",R40) -> 70.338549 | Y40: 1.36334 | Z40: =IF(Y40="","",IF(L40="Long",Y40-U40,U40-Y40)) -> 0.00108 | AA40: =IF(AB40="","",AB40*X40/1) -> 211.01565 | AB40: =IF(Z40="","",Z40*1/W40) -> 3 | AC40: 3 de Mario | AD40: 1.3619 | AE40: 0 | AF40: 0 | AG40: =-X40 -> -70.338549 | AH40: =IF(AG40="","",AG40+AF40+AE40) -> -70.338549 | AI40: =IF(AD40="","",IF(L40="Long",AD40-U40,U40-AD40)) -> -0.00036 | AJ40: =IF(AI40="","",AG40*S40/X40) -> -0.01 | AK40: =IF(AI40="","",(AG40+AF40+AE40)*S40/X40) -> -0.01 | AL40: =Q40+AG40 -> 6963.5163 | BH40: AUDSGD | BI40: =$BA$12 -> Exotics
B41: Testing em tempo real | C41: 31 | D41: 18 | E41: 4ª F | F41: 3 de Maio | G41: Tarde | H41: Majors | I41: GBPCAD | J41: Breakout | K41: 15s | L41: long | M41: L | Q41: =AL40 -> 6963.5163 | R41: =IF(Q41="","",S41*Q41/100%) -> 69.635163 | S41: 0.01 | T41: 0.01 | U41: 1.70853 | V41: 1.70802 | W41: =IF(V41="","",IF(L41="Long",U41-V41,V41-U41)) -> 0.00051 | X41: =IF(W41="","",R41) -> 69.635163 | Y41: 1.71006 | Z41: =IF(Y41="","",IF(L41="Long",Y41-U41,U41-Y41)) -> 0.00153 | AA41: =IF(AB41="","",AB41*X41/1) -> 208.90549 | AB41: =IF(Z41="","",Z41*1/W41) -> 3 | AC41: 3 de Maio | AD41: 1.70802 | AE41: 0 | AF41: 0 | AG41: =-X41 -> -69.635163 | AH41: =IF(AG41="","",AG41+AF41+AE41) -> -69.635163 | AI41: =IF(AD41="","",IF(L41="Long",AD41-U41,U41-AD41)) -> -0.00051 | AJ41: =IF(AI41="","",AG41*S41/X41) -> -0.01 | AK41: =IF(AI41="","",(AG41+AF41+AE41)*S41/X41) -> -0.01 | AL41: =Q41+AG41 -> 6893.8811 | BH41: CHFSGD | BI41: =$BA$12 -> Exotics
B42: Testing em tempo real | C42: 32 | D42: 18 | E42: 5ª F | F42: 4 de Maio | G42: Manhã | H42: Majors | I42: EURUSD | J42: Breakout | K42: 15s | L42: short | M42: W | Q42: =AL41 -> 6893.8811 | R42: =IF(Q42="","",S42*Q42/100%) -> 68.938811 | S42: 0.01 | T42: 0.04 | U42: 1.10536 | V42: 1.10584 | W42: =IF(V42="","",IF(L42="Long",U42-V42,V42-U42)) -> 0.00048 | X42: =IF(W42="","",R42) -> 68.938811 | Y42: 1.10387 | Z42: =IF(Y42="","",IF(L42="Long",Y42-U42,U42-Y42)) -> 0.00149 | AA42: =IF(AB42="","",AB42*X42/1) -> 213.99756 | AB42: =IF(Z42="","",Z42*1/W42) -> 3.1041667 | AC42: 4 de Maio | AD42: 1.10387 | AE42: 0 | AF42: 0 | AG42: =+AA42 -> 213.99756 | AH42: =IF(AG42="","",AG42+AF42+AE42) -> 213.99756 | AI42: =IF(AD42="","",IF(L42="Long",AD42-U42,U42-AD42)) -> 0.00149 | AJ42: =IF(AI42="","",AG42*S42/X42) -> 0.031041667 | AK42: =IF(AI42="","",(AG42+AF42+AE42)*S42/X42) -> 0.031041667 | AL42: =Q42+AG42 -> 7107.8787 | BH42: EURDKK | BI42: =$BA$12 -> Exotics
...

Sheet Weekly Analysis
A1: Nº da semana: | B1: 1 | C1: 2 | D1: 3 | E1: 4 | F1: 5 | G1: 6 | H1: 7 | I1: 8 | J1: 9 | K1: 10 | L1: 11 | M1: 12 | N1: 13 | O1: 14 | P1: 15 | Q1: 16 | R1: 17 | S1: 18 | T1: 19 | U1: 20 | V1: 21 | W1: 22 | X1: 23 | Y1: 24 | Z1: 25 | AA1: 26 | AB1: 27 | AC1: 28 | AD1: 29 | AE1: 30 | AF1: 31 | AG1: 32 | AH1: 33 | AI1: 34 | AJ1: 35 | AK1: 36 | AL1: 37 | AM1: 38 | AN1: 39 | AO1: 40 | AP1: 41 | AQ1: 42 | AR1: 43 | AS1: 44 | AT1: 45 | AU1: 46 | AV1: 47 | AW1: 48 | AX1: 49 | AY1: 50 | AZ1: 51 | BA1: 52
A2: Total de Operações Abertas: | B2: =COUNTIF('Registo de operações'!$D$11:$D$1001,B1) -> 0 | C2: =COUNTIF('Registo de operações'!$D$11:$D$1001,C1) -> 0 | D2: =COUNTIF('Registo de operações'!$D$11:$D$1001,D1) -> 0 | E2: =COUNTIF('Registo de operações'!$D$11:$D$1001,E1) -> 0 | F2: =COUNTIF('Registo de operações'!$D$11:$D$1001,F1) -> 9 | G2: =COUNTIF('Registo de operações'!$D$11:$D$1001,G1) -> 3 | H2: =COUNTIF('Registo de operações'!$D$11:$D$1001,H1) -> 10 | I2: =COUNTIF('Registo de operações'!$D$11:$D$1001,I1) -> 0 | ... BA2: =COUNTIF('Registo de operações'!$D$11:$D$1001,BA1) -> 0
A3: Total de Operações Vencedoras: | B3: =COUNTIFS('Registo de operações'!$D$11:$D$1001,B1,'Registo de operações'!$M$11:$M$1001,'Registo de operações'!$AW$10) -> 0 | C3: =COUNTIFS('Registo de operações'!$D$11:$D$1001,C1,'Registo de operações'!$M$11:$M$1001,'Registo de operações'!$AW$10) -> 0 | D3: =COUNTIFS('Registo de operações'!$D$11:$D$1001,D1,'Registo de operações'!$M$11:$M$1001,'Registo de operações'!$AW$10) -> 0 | E3: =COUNTIFS('Registo de operações'!$D$11:$D$1001,E1,'Registo de operações'!$M$11:$M$1001,'Registo de operações'!$AW$10) -> 0 | F3: =COUNTIFS('Registo de operações'!$D$11:$D$1001,F1,'Registo de operações'!$M$11:$M$1001,'Registo de operações'!$AW$10) -> 5 | G3: =COUNTIFS('Registo de operações'!$D$11:$D$1001,G1,'Registo de operações'!$M$11:$M$1001,'Registo de operações'!$AW$10) -> 1 | H3: =COUNTIFS('Registo de operações'!$D$11:$D$1001,H1,'Registo de operações'!$M$11:$M$1001,'Registo de operações'!$AW$10) -> 6 | I3: =COUNTIFS('Registo de operações'!$D$11:$D$1001,I1,'Registo de operações'!$M$11:$M$1001,'Registo de operações'!$AW$10) -> 0 | ... BA3: =COUNTIFS('Registo de operações'!$D$11:$D$1001,BA1,'Registo de operações'!$M$11:$M$1001,'Registo de operações'!$AW$10) -> 0
A4: Taxa de Acerto: | B4: =B3/B2 -> #DIV/0! | C4: =C3/C2 -> #DIV/0! | D4: =D3/D2 -> #DIV/0! | E4: =E3/E2 -> #DIV/0! | F4: =F3/F2 -> 0.55555556 | G4: =G3/G2 -> 0.33333333 | H4: =H3/H2 -> 0.6 | I4: =I3/I2 -> #DIV/0! | ... BA4: =BA3/BA2 -> #DIV/0!
A5: % Realizada: | B5: =SUMIFS('Registo de operações'!$AJ$11:$AJ$1001,'Registo de operações'!$D$11:$D$1001,'Weekly Analysis'!B1) -> 0 | C5: =SUMIFS('Registo de operações'!$AJ$11:$AJ$1001,'Registo de operações'!$D$11:$D$1001,'Weekly Analysis'!C1) -> 0 | D5: =SUMIFS('Registo de operações'!$AJ$11:$AJ$1001,'Registo de operações'!$D$11:$D$1001,'Weekly Analysis'!D1) -> 0 | E5: =SUMIFS('Registo de operações'!$AJ$11:$AJ$1001,'Registo de operações'!$D$11:$D$1001,'Weekly Analysis'!E1) -> 0 | F5: =SUMIFS('Registo de operações'!$AJ$11:$AJ$1001,'Registo de operações'!$D$11:$D$1001,'Weekly Analysis'!F1) -> 0.11112704 | G5: =SUMIFS('Registo de operações'!$AJ$11:$AJ$1001,'Registo de operações'!$D$11:$D$1001,'Weekly Analysis'!G1) -> 0.0046994536 | H5: =SUMIFS('Registo de operações'!$AJ$11:$AJ$1001,'Registo de operações'!$D$11:$D$1001,'Weekly Analysis'!H1) -> 0.14317308 | I5: =SUMIFS('Registo de operações'!$AJ$11:$AJ$1001,'Registo de operações'!$D$11:$D$1001,'Weekly Analysis'!I1) -> 0 | ... BA5: =SUMIFS('Registo de operações'!$AJ$11:$AJ$1001,'Registo de operações'!$D$11:$D$1001,'Weekly Analysis'!BA1) -> 0
A6: Capital Realizado: | B6: =SUMIFS('Registo de operações'!$AG$11:$AG$1001,'Registo de operações'!$D$11:$D$1001,'Weekly Analysis'!B1) -> 0 | C6: =SUMIFS('Registo de operações'!$AG$11:$AG$1001,'Registo de operações'!$D$11:$D$1001,'Weekly Analysis'!C1) -> 0 | D6: =SUMIFS('Registo de operações'!$AG$11:$AG$1001,'Registo de operações'!$D$11:$D$1001,'Weekly Analysis'!D1) -> 0 | E6: =SUMIFS('Registo de operações'!$AG$11:$AG$1001,'Registo de operações'!$D$11:$D$1001,'Weekly Analysis'!E1) -> 0 | F6: =SUMIFS('Registo de operações'!$AG$11:$AG$1001,'Registo de operações'!$D$11:$D$1001,'Weekly Analysis'!F1) -> 574.06519 | G6: =SUMIFS('Registo de operações'!$AG$11:$AG$1001,'Registo de operações'!$D$11:$D$1001,'Weekly Analysis'!G1) -> 24.012707 | H6: =SUMIFS('Registo de operações'!$AG$11:$AG$1001,'Registo de operações'!$D$11:$D$1001,'Weekly Analysis'!H1) -> 842.70885 | I6: =SUMIFS('Registo de operações'!$AG$11:$AG$1001,'Registo de operações'!$D$11:$D$1001,'Weekly Analysis'!I1) -> 0 | ... BA6: =SUMIFS('Registo de operações'!$AG$11:$AG$1001,'Registo de operações'!$D$11:$D$1001,'Weekly Analysis'!BA1) -> 0
A7: Objectivo Semanal | B7: 0.04 | C7: 0.04 | D7: 0.04 | E7: 0.04 | F7: 0.04 | G7: 0.04 | H7: 0.04 | I7: 0.04 | J7: 0.04 | K7: 0.04 | L7: 0.04 | M7: 0.04 | N7: 0.04 | O7: 0.06 | P7: 0.06 | Q7: 0.06 | R7: 0.06 | S7: 0.06 | T7: 0.06 | U7: 0.06 | V7: 0.06 | W7: 0.06 | X7: 0.06 | Y7: 0.06 | Z7: 0.06 | AA7: 0.06 | AB7: 0.06 | AC7: 0.06 | AD7: 0.06 | AE7: 0.06 | AF7: 0.06 | AG7: 0.06 | AH7: 0.06 | AI7: 0.06 | AJ7: 0.06 | AK7: 0.06 | AL7: 0.06 | AM7: 0.06 | AN7: 0.06 | AO7: 0.06 | AP7: 0.06 | AQ7: 0.06 | AR7: 0.06 | AS7: 0.06 | AT7: 0.06 | AU7: 0.06 | AV7: 0.06 | AW7: 0.06 | AX7: 0.06 | AY7: 0.06 | AZ7: 0.06 | BA7: 0.06
A9: Nº Total de operações negativas | B9: =COUNTIFS('Registo de operações'!$D$11:$D$1001,B1,'Registo de operações'!$M$11:$M$1001,'Registo de operações'!$AW$11) -> 0 | C9: =COUNTIFS('Registo de operações'!$D$11:$D$1001,C1,'Registo de operações'!$M$11:$M$1001,'Registo de operações'!$AW$11) -> 0 | D9: =COUNTIFS('Registo de operações'!$D$11:$D$1001,D1,'Registo de operações'!$M$11:$M$1001,'Registo de operações'!$AW$11) -> 0 | E9: =COUNTIFS('Registo de operações'!$D$11:$D$1001,E1,'Registo de operações'!$M$11:$M$1001,'Registo de operações'!$AW$11) -> 0 | F9: =COUNTIFS('Registo de operações'!$D$11:$D$1001,F1,'Registo de operações'!$M$11:$M$1001,'Registo de operações'!$AW$11) -> 4 | G9: =COUNTIFS('Registo de operações'!$D$11:$D$1001,G1,'Registo de operações'!$M$11:$M$1001,'Registo de operações'!$AW$11) -> 2 | H9: =COUNTIFS('Registo de operações'!$D$11:$D$1001,H1,'Registo de operações'!$M$11:$M$1001,'Registo de operações'!$AW$11) -> 4 | I9: =COUNTIFS('Registo de operações'!$D$11:$D$1001,I1,'Registo de operações'!$M$11:$M$1001,'Registo de operações'!$AW$11) -> 0 | ... BA9: =COUNTIFS('Registo de operações'!$D$11:$D$1001,BA1,'Registo de operações'!$M$11:$M$1001,'Registo de operações'!$AW$11) -> 0
A10: Volume de drawdown semanal | B10: =SUMIFS('Registo de operações'!$AJ$11:$AJ$1001,'Registo de operações'!$D$11:$D$1001,'Weekly Analysis'!B1,'Registo de operações'!$AJ$11:$AJ$1001,"<0") -> 0 | C10: =SUMIFS('Registo de operações'!$AJ$11:$AJ$1001,'Registo de operações'!$D$11:$D$1001,'Weekly Analysis'!C1,'Registo de operações'!$AJ$11:$AJ$1001,"<0") -> 0 | D10: =SUMIFS('Registo de operações'!$AJ$11:$AJ$1001,'Registo de operações'!$D$11:$D$1001,'Weekly Analysis'!D1,'Registo de operações'!$AJ$11:$AJ$1001,"<0") -> 0 | E10: =SUMIFS('Registo de operações'!$AJ$11:$AJ$1001,'Registo de operações'!$D$11:$D$1001,'Weekly Analysis'!E1,'Registo de operações'!$AJ$11:$AJ$1001,"<0") -> 0 | F10: =SUMIFS('Registo de operações'!$AJ$11:$AJ$1001,'Registo de operações'!$D$11:$D$1001,'Weekly Analysis'!F1,'Registo de operações'!$AJ$11:$AJ$1001,"<0") -> -0.04 | G10: =SUMIFS('Registo de operações'!$AJ$11:$AJ$1001,'Registo de operações'!$D$11:$D$1001,'Weekly Analysis'!G1,'Registo de operações'!$AJ$11:$AJ$1001,"<0") -> -0.02 | H10: =SUMIFS('Registo de operações'!$AJ$11:$AJ$1001,'Registo de operações'!$D$11:$D$1001,'Weekly Analysis'!H1,'Registo de operações'!$AJ$11:$AJ$1001,"<0") -> -0.04 | I10: =SUMIFS('Registo de operações'!$AJ$11:$AJ$1001,'Registo de operações'!$D$11:$D$1001,'Weekly Analysis'!I1,'Registo de operações'!$AJ$11:$AJ$1001,"<0") -> 0 | ... BA10: =SUMIFS('Registo de operações'!$AJ$11:$AJ$1001,'Registo de operações'!$D$11:$D$1001,'Weekly Analysis'!BA1,'Registo de operações'!$AJ$11:$AJ$1001,"<0") -> 0
A11: Média de perda por operação | B11: =AVERAGEIFS('Registo de operações'!$AJ$11:$AJ$1001,'Registo de operações'!$D$11:$D$1001,'Weekly Analysis'!B1,'Registo de operações'!$AJ$11:$AJ$1001,"<0") -> #DIV/0! | C11: =AVERAGEIFS('Registo de operações'!$AJ$11:$AJ$1001,'Registo de operações'!$D$11:$D$1001,'Weekly Analysis'!C1,'Registo de operações'!$AJ$11:$AJ$1001,"<0") -> #DIV/0! | D11: =AVERAGEIFS('Registo de operações'!$AJ$11:$AJ$1001,'Registo de operações'!$D$11:$D$1001,'Weekly Analysis'!D1,'Registo de operações'!$AJ$11:$AJ$1001,"<0") -> #DIV/0! | E11: =AVERAGEIFS('Registo de operações'!$AJ$11:$AJ$1001,'Registo de operações'!$D$11:$D$1001,'Weekly Analysis'!E1,'Registo de operações'!$AJ$11:$AJ$1001,"<0") -> #DIV/0! | F11: =AVERAGEIFS('Registo de operações'!$AJ$11:$AJ$1001,'Registo de operações'!$D$11:$D$1001,'Weekly Analysis'!F1,'Registo de operações'!$AJ$11:$AJ$1001,"<0") -> -0.01 | G11: =AVERAGEIFS('Registo de operações'!$AJ$11:$AJ$1001,'Registo de operações'!$D$11:$D$1001,'Weekly Analysis'!G1,'Registo de operações'!$AJ$11:$AJ$1001,"<0") -> -0.01 | H11: =AVERAGEIFS('Registo de operações'!$AJ$11:$AJ$1001,'Registo de operações'!$D$11:$D$1001,'Weekly Analysis'!H1,'Registo de operações'!$AJ$11:$AJ$1001,"<0") -> -0.01 | I11: =AVERAGEIFS('Registo de operações'!$AJ$11:$AJ$1001,'Registo de operações'!$D$11:$D$1001,'Weekly Analysis'!I1,'Registo de operações'!$AJ$11:$AJ$1001,"<0") -> #DIV/0! | ... BA11: =AVERAGEIFS('Registo de operações'!$AJ$11:$AJ$1001,'Registo de operações'!$D$11:$D$1001,'Weekly Analysis'!BA1,'Registo de operações'!$AJ$11:$AJ$1001,"<0") -> #DIV/0!
A12: Limite de drawdown semanal
A13: Limite de drawdown diário
A14: Média Limite de perda P/ Operação | B14: -0.005 | C14: -0.005 | D14: -0.005 | E14: -0.005 | F14: -0.005 | G14: -0.005 | H14: -0.005 | I14: -0.005 | J14: -0.005 | K14: -0.005 | L14: -0.005 | M14: -0.005 | N14: -0.005 | O14: -0.005 | P14: -0.005 | Q14: -0.005 | R14: -0.005 | S14: -0.005 | T14: -0.005 | U14: -0.005 | V14: -0.005 | W14: -0.005 | X14: -0.005 | Y14: -0.005 | Z14: -0.005 | AA14: -0.005 | AB14: -0.005 | AC14: -0.005 | AD14: -0.005 | AE14: -0.005 | AF14: -0.005 | AG14: -0.005 | AH14: -0.005 | AI14: -0.005 | AJ14: -0.005 | AK14: -0.005 | AL14: -0.005 | AM14: -0.005 | AN14: -0.005 | AO14: -0.005 | AP14: -0.005 | AQ14: -0.005 | AR14: -0.005 | AS14: -0.005 | AT14: -0.005 | AU14: -0.005 | AV14: -0.005 | AW14: -0.005 | AX14: -0.005 | AY14: -0.005 | AZ14: -0.005 | BA14: -0.005
A17: Análise da qualidade de trading
A18: Overtrading
A19: Análise das posições Positivas
A20: Análise das posições Negativas
A22: Avaliação semanal

Sheet Trading Plan
C1: Are you able to sustain 12 losses in a row?
B2: TRADING IS A SURVIVAL GAME. THOSE WHO PROTECT THEIR CAPITAL STAY IN THE GAME TO PLAY ANOTHER DAY.
B4: Todos o dias voam milhoes de euros sem dono - só precisamos de o saber agarra.
B5: O DINHEIRO ESTÁ ATRÁS DO MEDO
A8: Regras dos dias: | B8: Não operar a minutos ou segundos á segunda-feira
B9: Domingo é dia de organizar as operações a horas e dias
A10: Máximo de lucro: | B10: 5% \ semana
A11: Máximo de perdas: | B11: 3% \ semana
A12: Máximo de operações \ dia: | B12: 2 | C12: Na primeira com lucro, não opero para o dia \ Se me sentir confortável máx. 2 operações
C13: Na primeira em perda, dou uma segunda hipotse para o dia
A15: Nº Máximo de operações a Dia/Semana em Simultâneo: | B15: 2
A16: Nº Máximo de operações de 1H-12H em simulâneo: | B16: 2
A17: Nº Máximo de operações a Minutos em Simultâneo: | B17: 2
A18: Nº Máximo de operações Semanais: | B18: 5
A19: Exposição máxima de Conta em simultâneo | B19: =(B14+B15+B16)*B22 -> 0.02
A20: % de Risco Máximo por Operação | B20: 0.01 | C20: Objetivo no FTMO = 0,5% - Neste sentido conseguir agunetar com 20 trades negativos de seguida
A21: Nº Máximo de STOP-LOSS Diários | B21: 2
A22: Objectivo de % média de perda por operação negativa: | B22: 0.005
A24: % Máxima de Drawdown Mensal: | B24: 0.5 | C24: Depende de quanto eu fizer, quero conseguir tirar 1.500 para mim
A26: % Máxima de Drawdown Semanal:
A27: Nº Máximo de dias consecutivos só com Perdas: | B27: 2 \ 3 | C27: ex: 1 operação negativa por dia = 3% máximo da semana
C28: ex: 2 operações negativos num dia, e outra negativa noutro dia = 3% máximo da semana
A30: Valor que tiro como ordenado mensal: | B30: 1.500€
A31: Fundo de energência CGD: | B31: 5.000€
A32: Extra na conta FTMO para buffer: | B32: 0.1
A33: Minimo na conta pessoal IC market real: | B33: 10.000€
J34: Viver uma vida simples, livre do que a sociedade espera de nós. Quero estar rodeada de pessoas que transmitem boa energia, quero ser eu a tranmitir a boa energia. Viver livre de preconceitos, sentir-me amada por mim mesma sem a necessidade de aprovação do meio externo. Quero liberdade financeira, viajar muito por este mundo, ser capaz de me auto-sustentar, ter mais tempo para a minha familia, ter mais tempo para mim, aproveitar a vida rir sentir-me concretizada e fazer o que amo todos os dias - Animais, plantas, comida, natureza, paz | L34: WHAT | M34: GOAL | N34: PLAN
L35: Ordenado (A) + mochila ás costas (B) | M35: Trader profissional. Liberdade de trabalhar todos os dias para mim mesma. Com o meu exforço obtenho os meus resultados. Poder trabalhar de qualquer parte do mundo, viajar de mochila ás costas | N35: 0.6
L36: Fundo (s) | M36: Fundo de emergência; Sobrinhos; Animais; fundo c / Carlos; fundo para viajar de mochila ás costas e se precisar de algo! | N36: 0.2
J37: MY STRONG SIDE | K37: MY LESS STRONG SIDE | L37: Auto-caravana (C) | M37: Ter a minha casa e o meu conforto sobre rodas, sem pressas, Slow life, conhecer novas pessoas, novas habilidades pessoais.
J38: A minha intuição Jeito para pesquisar e me informar nos melhores sitios | K38: A indecisão sem dúvida, e o "medo" de perder o que já criei até este ponto. | L38: Terrano (D) | M38: Desejo um lugar tranquilo e silêncioso com espaço suficiente para ser auto sustêntável, com a praia relativamente perto. Consiga viver com paz e tranquila, na minha liberdade e forma de ser.
J39: VALORES PESSOAIS | K39: TIME | L39: Reforma (E) | N39: Compound 20%
J40: Respeito proprio Paz, calma Clareza Independência Sucesso | K40: 4 \ 5 H por dia Das 9h até as 13h da manhã | L40: Passive Income | M40: Outros planos, outros investimentos e projectos de coisas que me apaixonam.

Sheet Statistics
A3: Nº Entradas/Dia semana | B3: 2ª Feira | C3: 3ª Feira | D3: 4ª Feira | E3: 5ª Feira | F3: 6ª Feira | G3: TOTAL
B4: =COUNTIF('Registo de operações'!$E$11:$E$1001,'Registo de operações'!AS10) -> 10 | C4: =COUNTIF('Registo de operações'!$E$11:$E$211,'Registo de operações'!AS11) -> 11 | D4: =COUNTIF('Registo de operações'!$E$11:$E$211,'Registo de operações'!AS12) -> 16 | E4: =COUNTIF('Registo de operações'!$E$11:$E$211,'Registo de operações'!AS13) -> 24 | F4: =COUNTIF('Registo de operações'!$E$11:$E$211,'Registo de operações'!AS14) -> 16 | G4: =SUM(B4:F4) -> 77
A5: Acerto: | B5: =COUNTIFS('Registo de operações'!$E$11:$E$1001,'Registo de operações'!$AS$10,'Registo de operações'!$M$11:$M$1001,'Registo de operações'!$AW$10) -> 2 | C5: =COUNTIFS('Registo de operações'!$E$11:$E$1001,'Registo de operações'!$AS$11,'Registo de operações'!$M$11:$M$1001,'Registo de operações'!$AW$10) -> 5 | D5: =COUNTIFS('Registo de operações'!$E$11:$E$1001,'Registo de operações'!$AS$12,'Registo de operações'!$M$11:$M$1001,'Registo de operações'!$AW$10) -> 5 | E5: =COUNTIFS('Registo de operações'!$E$11:$E$1001,'Registo de operações'!$AS$13,'Registo de operações'!$M$11:$M$1001,'Registo de operações'!$AW$10) -> 11 | F5: =COUNTIFS('Registo de operações'!$E$11:$E$1001,'Registo de operações'!$AS$14,'Registo de operações'!$M$11:$M$1001,'Registo de operações'!$AW$10) -> 7
A6: Perda: | B6: =COUNTIFS('Registo de operações'!$E$11:$E$1001,'Registo de operações'!$AS$10,'Registo de operações'!$M$11:$M$1001,'Registo de operações'!$AW$11) -> 8 | C6: =COUNTIFS('Registo de operações'!$E$11:$E$1001,'Registo de operações'!$AS$11,'Registo de operações'!$M$11:$M$1001,'Registo de operações'!$AW$11) -> 6 | D6: =COUNTIFS('Registo de operações'!$E$11:$E$1001,'Registo de operações'!$AS$12,'Registo de operações'!$M$11:$M$1001,'Registo de operações'!$AW$11) -> 11 | E6: =COUNTIFS('Registo de operações'!$E$11:$E$1001,'Registo de operações'!$AS$13,'Registo de operações'!$M$11:$M$1001,'Registo de operações'!$AW$11) -> 13 | F6: =COUNTIFS('Registo de operações'!$E$11:$E$1001,'Registo de operações'!$AS$14,'Registo de operações'!$M$11:$M$1001,'Registo de operações'!$AW$11) -> 9
A7: Taxa de Acerto: | B7: =B5/B4 -> 0.2 | C7: =C5/C4 -> 0.45454545 | D7: =D5/D4 -> 0.3125 | E7: =E5/E4 -> 0.45833333 | F7: =F5/F4 -> 0.4375
A9: Marcos Temporais | B9: 3 Minutos | C9: 5 Minutos | D9: 15 Minutos | E9: 30 Minutos | F9: 1 Hora | G9: 2 Horas | H9: 4 Horas | I9: 8 Horas | J9: 1 Dia | K9: 1 Semana | L9: 15S | M9: 1m | N9: TOTAL
B10: =COUNTIF('Registo de operações'!$K$11:$K$211,'Registo de operações'!AV19) -> 12 | C10: =COUNTIF('Registo de operações'!$K$11:$K$211,'Registo de operações'!$AV$18) -> 8 | D10: =COUNTIF('Registo de operações'!$K$11:$K$211,'Registo de operações'!$AV$17) -> 1 | E10: =COUNTIF('Registo de operações'!$K$11:$K$211,'Registo de operações'!$AV$16) -> 1 | F10: =COUNTIF('Registo de operações'!$K$11:$K$211,'Registo de operações'!$AV$15) -> 4 | G10: =COUNTIF('Registo de operações'!$K$11:$K$211,'Registo de operações'!$AV$14) -> 3 | H10: =COUNTIF('Registo de operações'!$K$11:$K$211,'Registo de operações'!$AV$13) -> 3 | I10: =COUNTIF('Registo de operações'!$K$11:$K$211,'Registo de operações'!$AV$12) -> 2 | J10: =COUNTIF('Registo de operações'!$K$11:$K$211,'Registo de operações'!$AV$10) -> 2 | K10: =COUNTIF('Registo de operações'!$K$11:$K$211,'Registo de operações'!$AV$20) -> 0 | L10: =COUNTIF('Registo de operações'!$K$11:$K$211,'Registo de operações'!$AV$22) -> 16 | M10: =COUNTIF('Registo de operações'!$K$11:$K$211,'Registo de operações'!$AV$23) -> 25 | N10: =SUM(B10:M10) -> 77
A11: Acerto: | B11: =COUNTIFS('Registo de operações'!$K$11:$K$1001,'Registo de operações'!$AV$19,'Registo de operações'!$M$11:$M$1001,'Registo de operações'!$AW$10) -> 4 | C11: =COUNTIFS('Registo de operações'!$K$11:$K$1001,'Registo de operações'!$AV$18,'Registo de operações'!$M$11:$M$1001,'Registo de operações'!$AW$10) -> 6 | D11: =COUNTIFS('Registo de operações'!$K$11:$K$1001,'Registo de operações'!$AV$17,'Registo de operações'!$M$11:$M$1001,'Registo de operações'!$AW$10) -> 1 | E11: =COUNTIFS('Registo de operações'!$K$11:$K$1001,'Registo de operações'!$AV$16,'Registo de operações'!$M$11:$M$1001,'Registo de operações'!$AW$10) -> 0 | F11: =COUNTIFS('Registo de operações'!$K$11:$K$1001,'Registo de operações'!$AV$15,'Registo de operações'!$M$11:$M$1001,'Registo de operações'!$AW$10) -> 0 | G11: =COUNTIFS('Registo de operações'!$K$11:$K$1001,'Registo de operações'!$AV$14,'Registo de operações'!$M$11:$M$1001,'Registo de operações'!$AW$10) -> 1 | H11: =COUNTIFS('Registo de operações'!$K$11:$K$1001,'Registo de operações'!$AV$13,'Registo de operações'!$M$11:$M$1001,'Registo de operações'!$AW$10) -> 1 | I11: =COUNTIFS('Registo de operações'!$K$11:$K$1001,'Registo de operações'!$AV$12,'Registo de operações'!$M$11:$M$1001,'Registo de operações'!$AW$10) -> 0 | J11: =COUNTIFS('Registo de operações'!$K$11:$K$1001,'Registo de operações'!$AV$10,'Registo de operações'!$M$11:$M$1001,'Registo de operações'!$AW$10) -> 2 | K11: =COUNTIFS('Registo de operações'!$K$11:$K$1001,'Registo de operações'!$AV$20,'Registo de operações'!$M$11:$M$1001,'Registo de operações'!$AW$10) -> 0 | L11: =COUNTIFS('Registo de operações'!$K$11:$K$1001,'Registo de operações'!$AV$22,'Registo de operações'!$M$11:$M$1001,'Registo de operações'!$AW$10) -> 4 | M11: =COUNTIFS('Registo de operações'!$K$11:$K$1001,'Registo de operações'!$AV$23,'Registo de operações'!$M$11:$M$1001,'Registo de operações'!$AW$10) -> 11
A12: Perda: | B12: =COUNTIFS('Registo de operações'!$K$11:$K$1001,'Registo de operações'!$AV$19,'Registo de operações'!$M$11:$M$1001,'Registo de operações'!$AW$11) -> 8 | C12: =COUNTIFS('Registo de operações'!$K$11:$K$1001,'Registo de operações'!$AV$18,'Registo de operações'!$M$11:$M$1001,'Registo de operações'!$AW$11) -> 2 | D12: =COUNTIFS('Registo de operações'!$K$11:$K$1001,'Registo de operações'!$AV$17,'Registo de operações'!$M$11:$M$1001,'Registo de operações'!$AW$11) -> 0 | E12: =COUNTIFS('Registo de operações'!$K$11:$K$1001,'Registo de operações'!$AV$16,'Registo de operações'!$M$11:$M$1001,'Registo de operações'!$AW$11) -> 1 | F12: =COUNTIFS('Registo de operações'!$K$11:$K$1001,'Registo de operações'!$AV$15,'Registo de operações'!$M$11:$M$1001,'Registo de operações'!$AW$11) -> 4 | G12: =COUNTIFS('Registo de operações'!$K$11:$K$1001,'Registo de operações'!$AV$14,'Registo de operações'!$M$11:$M$1001,'Registo de operações'!$AW$11) -> 2 | H12: =COUNTIFS('Registo de operações'!$K$11:$K$1001,'Registo de operações'!$AV$13,'Registo de operações'!$M$11:$M$1001,'Registo de operações'!$AW$11) -> 2 | I12: =COUNTIFS('Registo de operações'!$K$11:$K$1001,'Registo de operações'!$AV$12,'Registo de operações'!$M$11:$M$1001,'Registo de operações'!$AW$11) -> 2 | J12: =COUNTIFS('Registo de operações'!$K$11:$K$1001,'Registo de operações'!$AV$10,'Registo de operações'!$M$11:$M$1001,'Registo de operações'!$AW$11) -> 0 | K12: =COUNTIFS('Registo de operações'!$K$11:$K$1001,'Registo de operações'!$AV$20,'Registo de operações'!$M$11:$M$1001,'Registo de operações'!$AW$11) -> 0 | L12: =COUNTIFS('Registo de operações'!$K$11:$K$1001,'Registo de operações'!$AV$22,'Registo de operações'!$M$11:$M$1001,'Registo de operações'!$AW$11) -> 12 | M12: =COUNTIFS('Registo de operações'!$K$11:$K$1001,'Registo de operações'!$AV$23,'Registo de operações'!$M$11:$M$1001,'Registo de operações'!$AW$11) -> 14
A13: Taxa de Acerto: | B13: =B11/B10 -> 0.33333333 | C13: =C11/C10 -> 0.75 | D13: =D11/D10 -> 1 | E13: =E11/E10 -> 0 | F13: =F11/F10 -> 0 | G13: =G11/G10 -> 0.33333333 | H13: =H11/H10 -> 0.33333333 | I13: =I11/I10 -> 0 | ... M13: =M11/M10 -> 0.44
A15: Entradas por estratégia | B15: BreakOut | C15: Bandeira | D15: Retest | E15: Total
B16: =COUNTIF('Registo de operações'!$J$11:$J$1001,'Registo de operações'!AU11) -> 71 | C16: =COUNTIF('Registo de operações'!$J$11:$J$1001,'Registo de operações'!AU12) -> 0 | D16: =COUNTIF('Registo de operações'!$J$11:$J$1001,'Registo de operações'!AU10) -> 6 | E16: =SUM(B16:D16) -> 77
A17: Acerto: | B17: =COUNTIFS('Registo de operações'!$J$11:$J$1001,'Registo de operações'!$AU$11,'Registo de operações'!$M$11:$M$1001,'Registo de operações'!AW10) -> 29 | C17: =COUNTIFS('Registo de operações'!$J$11:$J$1001,'Registo de operações'!$AU$12,'Registo de operações'!$M$11:$M$1001,'Registo de operações'!AW10) -> 0 | D17: =COUNTIFS('Registo de operações'!$J$11:$J$1001,'Registo de operações'!$AU$10,'Registo de operações'!$M$11:$M$1001,'Registo de operações'!AW10) -> 1
A18: Perda: | B18: =COUNTIFS('Registo de operações'!$J$11:$J$1001,'Registo de operações'!$AU$11,'Registo de operações'!$M$11:$M$1001,'Registo de operações'!AW11) -> 42 | C18: =COUNTIFS('Registo de operações'!$J$11:$J$1001,'Registo de operações'!$AU$12,'Registo de operações'!$M$11:$M$1001,'Registo de operações'!AW11) -> 0 | D18: =COUNTIFS('Registo de operações'!$J$11:$J$1001,'Registo de operações'!$AU$10,'Registo de operações'!$M$11:$M$1001,'Registo de operações'!AW11) -> 5
A19: Taxa de Acerto estratégia: | B19: =B17/B16 -> 0.4084507 | C19: =C17/C16 -> #DIV/0! | D19: =D17/D16 -> 0.16666667
A21: Pares | B21: AUDCAD | C21: AUDCHF | D21: AUDJPY | E21: AUDNZD | F21: AUDUSD | G21: CADJPY | H21: EURAUD | I21: EURJPY | J21: EURUSD | K21: GBPCAD | L21: GBPJPY | M21: GBPUSD | N21: NZDUSD | O21: USDCAD | P21: USDJPY | Q21: USDSGD | R21: EURGBP
B22: =COUNTIF('Registo de operações'!$I$11:$I$211,'Registo de operações'!$BH$17) -> 3 | C22: =COUNTIF('Registo de operações'!$I$11:$I$211,'Registo de operações'!$BH$18) -> 3 | D22: =COUNTIF('Registo de operações'!$I$11:$I$211,'Registo de operações'!$BH$19) -> 3 | E22: =COUNTIF('Registo de operações'!$I$11:$I$211,'Registo de operações'!$BH$20) -> 2 | F22: =COUNTIF('Registo de operações'!$I$11:$I$211,'Registo de operações'!$BH$11) -> 2 | G22: =COUNTIF('Registo de operações'!$I$11:$I$211,'Registo de operações'!$BH$22) -> 7 | H22: =COUNTIF('Registo de operações'!$I$11:$I$211,'Registo de operações'!$BH$24) -> 1 | I22: =COUNTIF('Registo de operações'!$I$11:$I$211,'Registo de operações'!$BH$28) -> 2 | J22: =COUNTIF('Registo de operações'!$I$11:$I$211,'Registo de operações'!$BH$10) -> 6 | K22: =COUNTIF('Registo de operações'!$I$11:$I$211,'Registo de operações'!$BH$31) -> 5 | L22: =COUNTIF('Registo de operações'!$I$11:$I$211,'Registo de operações'!$BH$33) -> 2 | M22: =COUNTIF('Registo de operações'!$I$11:$I$211,'Registo de operações'!$BH$13) -> 10 | N22: =COUNTIF('Registo de operações'!$I$11:$I$211,'Registo de operações'!$BH$38) -> 3 | O22: =COUNTIF('Registo de operações'!$I$11:$I$211,'Registo de operações'!$BH$14) -> 4 | P22: =COUNTIF('Registo de operações'!$I$11:$I$211,'Registo de operações'!$BH$16) -> 3 | Q22: =COUNTIF('Registo de operações'!$I$11:$I$211,'Registo de operações'!$BH$39) -> 1 | R22: =COUNTIF('Registo de operações'!$I$11:$I$211,'Registo de operações'!$BH$27) -> 3
