Workbook

Sheet Registo de operações
M2: Fundos iniciais | Q2: Mov. Add. Fundos | R2: Profit | S2: Current Funds | U2: Risk | V2: Total | Y2: Average | AC2: Comissões | AD2: Swaps | AE2: Capital liquido Gerado | AF2: Efective % (W. Add. Funds) | AG2: RRR Liquido Realizado
E3: Nº Op | F3: % Win | G3: Win | H3: Lose | I3: NEUTRO | V3: Win | W3: Loss | X3: Total | Y3: Win | Z3: Loss | AA3: Total
E4: =COUNTA(U11:U211) -> 81 | F4: =G4/100%/(E4-I4) -> 0.36486486 | G4: =COUNTIF(M11:M211,"W") -> 27 | H4: =COUNTIF(M11:M211,"L") -> 47 | I4: =E4-G4-H4 -> 7 | M4: 10000 | Q4: 0 | R4: =SUM((X5)+(AD4)+(AC4)) -> -624.36224 | S4: =SUM((M4)+(Q4)+(R4)) -> 9375.6378 | U4: 0.01 | V4: =Pontuação!B2 -> 0.43638742 | W4: =Pontuação!C2 -> -0.43733417 | X4: =SUM(Tabela2[[Ganhos %]:[Perdas %]]) -> -0.00094675072 | Y4: =Pontuação!B3 -> 0.014546247 | Z4: =Pontuação!C3 -> -0.0089251872 | AA4: =AVERAGE(Tabela2[[Ganhos %]:[Perdas %]]) -> -1.1984186e-05 | AC4: =SUM(AE11:AE211) -> -564.39 | AD4: =SUM(AF11:AF211) -> 0.24 | AE4: =SUM((V5)+(W5)+(AC4)+(AD4)) -> -624.36224 | AF4: =SUM((AE4*100)/(M4+Q4))/100 -> -0.062436224 | AG4: =SUM(AK11:AK211) -> -0.058406776
V5: =Pontuação!D2 -> 4242.6641 | W5: =Pontuação!E2 -> -4302.8764 | X5: =SUM(Tabela2[[Ganhos €]:[Perdas €]]) -> -60.212236 | Y5: =Pontuação!D3 -> 141.42214 | Z5: =Pontuação!E3 -> -87.813803 | AA5: =AVERAGE(Tabela2[[Ganhos €]:[Perdas €]]) -> -0.7621802
B7: TIPO | C7: Nº T | D7: Nº S | E7: Dia da semana | F7: DATA | G7: Hora | H7: Grupo | I7: Par/Produto | J7: estratégia | K7: Marco Temporal | L7: Tipo de entrada | M7: W L | N7: E | O7: G | P7: S | Q7: Starting Position | V7: Stop Loss | Y7: Take Profit | AC7: Close Position | AL7: TOTAL depois da operação
Q8: Account Funds | R8: € Risk | S8: % Risk | T8: Lot | U8: Position entry | V8: Max Loss | W8: Pips | X8: € Loss | Y8: Take Profit | Z8: Pips | AA8: € Gain | AB8: RRR | AC8: Day Close | AD8: Closing price | AE8: Comissão | AF8: Swap | AG8: Lucro | AH8: Lucro liquido | AI8: Pips Close | AJ8: RRR Realizado | AK8: RRR Liquido | BH8: Currency | BI8: Grup | BJ8: Avaliação das Entradas:
A9: , | AR9: Sentido | AS9: Day W | AT9: Hora | AU9: Estratégia | AV9: Time Frame | AW9: W L | AX9: O C | AY9: News | AZ9: Candle | BA9: Grup | BB9: Emotional state
AR10: Short | AS10: 2ª F | AT10: Londres | AU10: BSL | AV10: 1D | AW10: W | AX10: O | AY10: Yes | AZ10: Open | BA10: Majors | BB10: Impatience | BC10: x | BD10: 0 | BE10: 0 | BF10: -1 | BG10: x | BH10: EURUSD | BI10: =$BA$10 -> Majors
B11: Fusion demo | C11: 77 | D11: 4 | E11: 2ª F | F11: 22 de Janeiro | G11: Londres | H11: Minors | I11: AUDUSD | J11: ICT | K11: 30m | L11: Short | M11: L | Q11: 10000 | R11: =IF(Q11="","",S11*Q11/100%) -> 100 | S11: 0.01 | U11: 0.65724 | V11: 0.66006 | W11: =IF(V11="","",IF(L11="Long",U11-V11,V11-U11)) -> 0.00282 | X11: =IF(W11="","",R11) -> 100 | Y11: 0.65124 | Z11: =IF(Y11="","",IF(L11="Long",Y11-U11,U11-Y11)) -> 0.006 | AA11: =IF(AB11="","",AB11*X11/1) -> 212.76596 | AB11: =IF(Z11="","",Z11*1/W11) -> 2.1276596 | AC11: 22 de Janeiro | AD11: =V11 -> 0.66006 | AE11: -1.54 | AF11: 0.24 | AG11: =-X11 -> -100 | AH11: =IF(AG11="","",AG11+AF11+AE11) -> -101.3 | AI11: =IF(AD11="","",IF(L11="Long",AD11-U11,U11-AD11)) -> -0.00282 | AJ11: =IF(AI11="","",AG11*S11/X11) -> -0.01 | AK11: =IF(AI11="","",(AG11+AF11+AE11)*S11/X11) -> -0.01013 | AL11: =Q11+AH11 -> 9898.7 | AR11: Long | AS11: 3ª F | AT11: NY | AU11: SSL | AV11: 12h | AW11: L | AX11: C | AY11: No | AZ11: Close | BA11: Minors | BB11: Fear | BD11: 0.1 | BE11: 0.1 | BF11: 0 | BH11: AUDUSD | BI11: =$BA$10 -> Majors | BL11: A | BM11: Boa entrada - Com estratégia - No timming Correto - Boa probabilidade
B12: Fusion demo | C12: 78 | D12: 5 | E12: 5ª F | F12: 1 de Fevereiro | G12: Londres | H12: Majors | I12: EURUSD | J12: ICT | K12: 1m | L12: Short | M12: L | Q12: =AL11 -> 9898.7 | R12: =IF(Q12="","",S12*Q12/100%) -> 98.987 | S12: 0.01 | U12: 1.08129 | V12: 1.0816 | W12: =IF(V12="","",IF(L12="Long",U12-V12,V12-U12)) -> 0.00031 | X12: =IF(W12="","",R12) -> 98.987 | Y12: 1.08033 | Z12: =IF(Y12="","",IF(L12="Long",Y12-U12,U12-Y12)) -> 0.00096 | AA12: =IF(AB12="","",AB12*X12/1) -> 306.54039 | AB12: =IF(Z12="","",Z12*1/W12) -> 3.0967742 | AC12: 2 de Fevereiro | AD12: =V12 -> 1.0816 | AE12: -13.98 | AF12: 0 | AG12: =-X12 -> -98.987 | AH12: =IF(AG12="","",AG12+AF12+AE12) -> -112.967 | AI12: =IF(AD12="","",IF(L12="Long",AD12-U12,U12-AD12)) -> -0.00031 | AJ12: =IF(AI12="","",AG12*S12/X12) -> -0.01 | AK12: =IF(AI12="","",(AG12+AF12+AE12)*S12/X12) -> -0.011412307 | AL12: =Q12+AH12 -> 9785.733 | AS12: 4ª F | AT12: Asia | AU12: FVG | AV12: 8h | AW12: N | AY12: n/a | AZ12: Next | BA12: Exotics | BB12: Greed | BD12: 0.2 | BE12: 0.2 | BF12: 1 | BH12: GBPCHF | BI12: =$BA$10 -> Majors | BL12: B | BM12: Boa entrada - Com alguma estratégia - Alguma Probabilidade
B13: Fusion demo | C13: 79 | D13: 5 | E13: 5ª F | F13: 1 de Fevereiro | G13: Londres | H13: Majors | I13: EURUSD | J13: ICT | K13: 1m | L13: Short | M13: L | Q13: =AL12 -> 9785.733 | R13: =IF(Q13="","",S13*Q13/100%) -> 97.85733 | S13: 0.01 | U13: 1.08154 | V13: 1.08178 | W13: =IF(V13="","",IF(L13="Long",U13-V13,V13-U13)) -> 0.00024 | X13: =IF(W13="","",R13) -> 97.85733 | Y13: 1.08034 | Z13: =IF(Y13="","",IF(L13="Long",Y13-U13,U13-Y13)) -> 0.0012 | AA13: =IF(AB13="","",AB13*X13/1) -> 489.28665 | AB13: =IF(Z13="","",Z13*1/W13) -> 5 | AC13: 2 de Fevereiro | AD13: =V13 -> 1.08178 | AE13: -18.64 | AF13: 0 | AG13: =-X13 -> -97.85733 | AH13: =IF(AG13="","",AG13+AF13+AE13) -> -116.49733 | AI13: =IF(AD13="","",IF(L13="Long",AD13-U13,U13-AD13)) -> -0.00024 | AJ13: =IF(AI13="","",AG13*S13/X13) -> -0.01 | AK13: =IF(AI13="","",(AG13+AF13+AE13)*S13/X13) -> -0.011904814 | AL13: =Q13+AH13 -> 9669.2357 | AS13: 5ª F | AU13: OB | AV13: 4h | AZ13: n/a | BA13: Indices | BB13: Hope | BD13: 0.3 | BE13: 0.3 | BF13: 2 | BH13: GBPUSD | BI13: =$BA$10 -> Majors | BL13: C | BM13: Razoavél - Com alguma estratégia - Mas impulsiva
B14: Fusion demo | C14: 80 | D14: 6 | E14: 4ª F | F14: 7 de Fevereiro | G14: Londres | H14: Majors | I14: EURUSD | J14: ICT | K14: 1m | L14: Short | M14: L | Q14: =AL13 -> 9669.2357 | R14: =IF(Q14="","",S14*Q14/100%) -> 96.692357 | S14: 0.01 | U14: 1.0769 | V14: 1.07709 | W14: =IF(V14="","",IF(L14="Long",U14-V14,V14-U14)) -> 0.00019 | X14: =IF(W14="","",R14) -> 96.692357 | Y14: 1.07633 | Z14: =IF(Y14="","",IF(L14="Long",Y14-U14,U14-Y14)) -> 0.00057 | AA14: =IF(AB14="","",AB14*X14/1) -> 290.07707 | AB14: =IF(Z14="","",Z14*1/W14) -> 3 | AC14: 7 de Janeiro | AD14: =V14 -> 1.07709 | AE14: -22.16 | AF14: 0 | AG14: =-X14 -> -96.692357 | AH14: =IF(AG14="","",AG14+AF14+AE14) -> -118.85236 | AI14: =IF(AD14="","",IF(L14="Long",AD14-U14,U14-AD14)) -> -0.00019 | AJ14: =IF(AI14="","",AG14*S14/X14) -> -0.01 | AK14: =IF(AI14="","",(AG14+AF14+AE14)*S14/X14) -> -0.012291805 | AL14: =Q14+AH14 -> 9550.3833 | AS14: 6ª F | AV14: 2h | BA14: Futures | BB14: Confidence | BD14: 0.4 | BE14: 0.4 | BF14: 3 | BH14: USDCAD | BI14: =$BA$10 -> Majors | BL14: D | BM14: Má entrada - Sem estratégia e impulsiva
B15: FTMO challenge 1 | C15: 81 | D15: 12 | E15: 3ª F | F15: 19 de Março | G15: Londres | H15: Majors | I15: AUDUSD | J15: ICT | K15: 1m | L15: Long | M15: W | Q15: =AL14 -> 9550.3833 | R15: =IF(Q15="","",S15*Q15/100%) -> 95.503833 | S15: 0.01 | U15: 0.65107 | V15: 0.65086 | W15: =IF(V15="","",IF(L15="Long",U15-V15,V15-U15)) -> 0.00021 | X15: =IF(W15="","",R15) -> 95.503833 | Y15: 0.65158 | Z15: =IF(Y15="","",IF(L15="Long",Y15-U15,U15-Y15)) -> 0.00051 | AA15: =IF(AB15="","",AB15*X15/1) -> 231.93788 | AB15: =IF(Z15="","",Z15*1/W15) -> 2.4285714 | AC15: 19 de Março | AD15: =Y15 -> 0.65158 | AE15: -13.61 | AF15: 0 | AG15: =AA15 -> 231.93788 | AH15: =IF(AG15="","",AG15+AF15+AE15) -> 218.32788 | AI15: =IF(AD15="","",IF(L15="Long",AD15-U15,U15-AD15)) -> 0.00051 | AJ15: =IF(AI15="","",AG15*S15/X15) -> 0.024285714 | AK15: =IF(AI15="","",(AG15+AF15+AE15)*S15/X15) -> 0.022860641 | AL15: =Q15+AH15 -> 9768.7112 | AV15: 1h | BB15: Uncertainty | BD15: 0.5 | BE15: 0.5 | BF15: 4 | BH15: USDCHF | BI15: =$BA$10 -> Majors
B16: FTMO challenge 1 | C16: 82 | D16: 12 | E16: 5ª F | F16: 21 de Março | G16: Londres | H16: Majors | I16: EURUSD | J16: ICT | K16: 1m | L16: Short | M16: W | Q16: =AL15 -> 9768.7112 | R16: =IF(Q16="","",S16*Q16/100%) -> 97.687112 | S16: 0.01 | U16: 1.09349 | V16: 1.09389 | W16: =IF(V16="","",IF(L16="Long",U16-V16,V16-U16)) -> 0.0004 | X16: =IF(W16="","",R16) -> 97.687112 | Y16: 1.09233 | Z16: =IF(Y16="","",IF(L16="Long",Y16-U16,U16-Y16)) -> 0.00116 | AA16: =IF(AB16="","",AB16*X16/1) -> 283.29262 | AB16: =IF(Z16="","",Z16*1/W16) -> 2.9 | AC16: 21 de Março | AD16: =Y16 -> 1.09233 | AE16: -7.66 | AF16: 0 | AG16: =AA16 -> 283.29262 | AH16: =IF(AG16="","",AG16+AF16+AE16) -> 275.63262 | AI16: =IF(AD16="","",IF(L16="Long",AD16-U16,U16-AD16)) -> 0.00116 | AJ16: =IF(AI16="","",AG16*S16/X16) -> 0.029 | AK16: =IF(AI16="","",(AG16+AF16+AE16)*S16/X16) -> 0.028215864 | AL16: =Q16+AH16 -> 10044.344 | AV16: 30m | BB16: Serene | BD16: 0.6 | BE16: 0.6 | BF16: 5 | BH16: USDJPY | BI16: =$BA$10 -> Majors | BJ16: Avaliação da Gestão
B17: FTMO challenge 1 | C17: 83 | D17: 13 | E17: 3ª F | F17: 26 de Março | G17: Londres | H17: Majors | I17: EURUSD | J17: ICT | K17: 5m | L17: Short | M17: W | Q17: =AL16 -> 10044.344 | R17: =IF(Q17="","",S17*Q17/100%) -> 100.44344 | S17: 0.01 | U17: 1.08491 | V17: 1.08533 | W17: =IF(V17="","",IF(L17="Long",U17-V17,V17-U17)) -> 0.00042 | X17: =IF(W17="","",R17) -> 100.44344 | Y17: 1.08368 | Z17: =IF(Y17="","",IF(L17="Long",Y17-U17,U17-Y17)) -> 0.00123 | AA17: =IF(AB17="","",AB17*X17/1) -> 294.15578 | AB17: =IF(Z17="","",Z17*1/W17) -> 2.9285714 | AC17: 26 de Março | AD17: 1.08424 | AE17: -7.33 | AF17: 0 | AG17: 163 | AH17: =IF(AG17="","",AG17+AF17+AE17) -> 155.67 | AI17: =IF(AD17="","",IF(L17="Long",AD17-U17,U17-AD17)) -> 0.00067 | AJ17: =IF(AI17="","",AG17*S17/X17) -> 0.016228039 | AK17: =IF(AI17="","",(AG17+AF17+AE17)*S17/X17) -> 0.015498275 | AL17: =Q17+AH17 -> 10200.014 | AV17: 15m | BD17: 0.7 | BE17: 0.7 | BF17: 6 | BH17: AUDCAD | BI17: =$BA$11 -> Minors | BL17: A | BM17: Trailing Stop com a sequência de máximos e minimos - Confortável com a posição - Posição encaminhada
B18: FTMO challenge 1 | C18: 84 | D18: 13 | E18: 5ª F | F18: 28 de Março | G18: Londres | H18: Majors | I18: EURUSD | J18: ICT | K18: 1m | L18: Long | M18: L | Q18: =AL17 -> 10200.014 | R18: =IF(Q18="","",S18*Q18/100%) -> 102.00014 | S18: 0.01 | U18: 1.07935 | V18: 1.07894 | W18: =IF(V18="","",IF(L18="Long",U18-V18,V18-U18)) -> 0.00041 | X18: =IF(W18="","",R18) -> 102.00014 | Y18: 1.08002 | Z18: =IF(Y18="","",IF(L18="Long",Y18-U18,U18-Y18)) -> 0.00067 | AA18: =IF(AB18="","",AB18*X18/1) -> 166.68315 | AB18: =IF(Z18="","",Z18*1/W18) -> 1.6341463 | AC18: 28 de Março | AD18: =V18 -> 1.07894 | AE18: -7.98 | AF18: 0 | AG18: =-X18 -> -102.00014 | AH18: =IF(AG18="","",AG18+AF18+AE18) -> -109.98014 | AI18: =IF(AD18="","",IF(L18="Long",AD18-U18,U18-AD18)) -> -0.00041 | AJ18: =IF(AI18="","",AG18*S18/X18) -> -0.01 | AK18: =IF(AI18="","",(AG18+AF18+AE18)*S18/X18) -> -0.010782352 | AL18: =Q18+AH18 -> 10090.034 | AV18: 5m | BD18: 0.8 | BE18: 0.8 | BF18: 7 | BH18: AUDCHF | BI18: =$BA$11 -> Minors | BL18: B | BM18: Trailing Stop com a sequência de máximos e minimos - Preocupação com a posição - Posição a perder estrutura
B19: FTMO challenge 1 | C19: 85 | D19: 14 | E19: 3ª F | F19: 2 de Arbil | G19: NY | H19: Majors | I19: AUDUSD | J19: ICT | K19: 1m | L19: Short | M19: W | Q19: =AL18 -> 10090.034 | R19: =IF(Q19="","",S19*Q19/100%) -> 100.90034 | S19: 0.01 | U19: 0.65041 | V19: 0.65072 | W19: =IF(V19="","",IF(L19="Long",U19-V19,V19-U19)) -> 0.00031 | X19: =IF(W19="","",R19) -> 100.90034 | Y19: 0.64886 | Z19: =IF(Y19="","",IF(L19="Long",Y19-U19,U19-Y19)) -> 0.00155 | AA19: =IF(AB19="","",AB19*X19/1) -> 504.50168 | AB19: =IF(Z19="","",Z19*1/W19) -> 5 | AC19: 2 de Abril | AD19: 0.65021 | AE19: -10.52 | AF19: 0 | AG19: 70.16 | AH19: =IF(AG19="","",AG19+AF19+AE19) -> 59.64 | AI19: =IF(AD19="","",IF(L19="Long",AD19-U19,U19-AD19)) -> 0.0002 | AJ19: =IF(AI19="","",AG19*S19/X19) -> 0.006953396 | AK19: =IF(AI19="","",(AG19+AF19+AE19)*S19/X19) -> 0.005910783 | AL19: =Q19+AH19 -> 10149.674 | AV19: 3m | BD19: 0.9 | BE19: 0.9 | BF19: 8 | BH19: AUDJPY | BI19: =$BA$11 -> Minors | BL19: C | BM19: Alteração do stop sem estratégia de máximos e minimos - Preocupação com a posição
B20: FTMO challenge 1 | C20: 86 | D20: 14 | E20: 4ª F | F20: 3 de Abril | G20: NY | H20: Majors | I20: EURUSD | J20: ICT | K20: 1m | L20: Short | Q20: =AL19 -> 10149.674 | R20: =IF(Q20="","",S20*Q20/100%) -> 101.49674 | S20: 0.01 | U20: 1.07809 | V20: 1.07851 | W20: =IF(V20="","",IF(L20="Long",U20-V20,V20-U20)) -> 0.00042 | X20: =IF(W20="","",R20) -> 101.49674 | Y20: 1.07706 | Z20: =IF(Y20="","",IF(L20="Long",Y20-U20,U20-Y20)) -> 0.00103 | AA20: =IF(AB20="","",AB20*X20/1) -> 248.90866 | AB20: =IF(Z20="","",Z20*1/W20) -> 2.452381 | AC20: 3 de Abril | AD20: 1.97817 | AE20: -7.56 | AF20: 0 | AG20: -20.18 | AH20: =IF(AG20="","",AG20+AF20+AE20) -> -27.74 | AI20: =IF(AD20="","",IF(L20="Long",AD20-U20,U20-AD20)) -> -0.90008 | AJ20: =IF(AI20="","",AG20*S20/X20) -> -0.0019882413 | AK20: =IF(AI20="","",(AG20+AF20+AE20)*S20/X20) -> -0.0027330928 | AL20: =Q20+AH20 -> 10121.934 | AV20: 1S | BD20: 1 | BE20: 1 | BH20: AUDNZD | BI20: =$BA$11 -> Minors | BL20: D | BM20: Sem Gestão - Não Fechei após a 1ª/2ª vela negativa
B21: FTMO challenge 1 | C21: 87 | D21: 14 | E21: 5ª F | F21: 4 de Abril | G21: NY | H21: Majors | I21: EURUSD | J21: ICT | K21: 1m | L21: Long | Q21: =AL20 -> 10121.934 | R21: =IF(Q21="","",S21*Q21/100%) -> 101.21934 | S21: 0.01 | U21: 1.086689 | V21: 1.08637 | W21: =IF(V21="","",IF(L21="Long",U21-V21,V21-U21)) -> 0.000319 | X21: =IF(W21="","",R21) -> 101.21934 | Y21: 1.08787 | Z21: =IF(Y21="","",IF(L21="Long",Y21-U21,U21-Y21)) -> 0.001181 | AA21: =IF(AB21="","",AB21*X21/1) -> 374.73366 | AB21: =IF(Z21="","",Z21*1/W21) -> 3.7021944 | AC21: 4 de Abril | AD21: =U21 -> 1.086689 | AE21: -6.1 | AF21: 0 | AG21: 0 | AH21: =IF(AG21="","",AG21+AF21+AE21) -> -6.1 | AI21: =IF(AD21="","",IF(L21="Long",AD21-U21,U21-AD21)) -> 0 | AJ21: =IF(AI21="","",AG21*S21/X21) -> 0 | AK21: =IF(AI21="","",(AG21+AF21+AE21)*S21/X21) -> -0.00060265165 | AL21: =Q21+AH21 -> 10115.834 | AV21: 6h | BH21: CADCHF | BI21: =$BA$11 -> Minors
B22: FTMO challenge 1 | C22: 88 | D22: 14 | E22: 6ª F | F22: 5 de Abril | G22: NY | H22: Majors | I22: AUDUSD | J22: ICT | K22: 1m | L22: Long | M22: L | Q22: =AL21 -> 10115.834 | R22: =IF(Q22="","",S22*Q22/100%) -> 101.15834 | S22: 0.01 | U22: 0.65855 | V22: 0.65829 | W22: =IF(V22="","",IF(L22="Long",U22-V22,V22-U22)) -> 0.00026 | X22: =IF(W22="","",R22) -> 101.15834 | Y22: 0.65877 | Z22: =IF(Y22="","",IF(L22="Long",Y22-U22,U22-Y22)) -> 0.00022 | AA22: =IF(AB22="","",AB22*X22/1) -> 85.595516 | AB22: =IF(Z22="","",Z22*1/W22) -> 0.84615385 | AC22: 5 de Abril | AD22: 0.65829 | AE22: -12.18 | AF22: 0 | AG22: -52.79 | AH22: =IF(AG22="","",AG22+AF22+AE22) -> -64.97 | AI22: =IF(AD22="","",IF(L22="Long",AD22-U22,U22-AD22)) -> -0.00026 | AJ22: =IF(AI22="","",AG22*S22/X22) -> -0.0052185516 | AK22: =IF(AI22="","",(AG22+AF22+AE22)*S22/X22) -> -0.0064226046 | AL22: =Q22+AH22 -> 10050.864 | AV22: 15s | BH22: CADJPY | BI22: =$BA$11 -> Minors | BJ22: Avaliação da Saída
B23: FTMO challenge 1 | C23: 89 | D23: 14 | E23: 6ª F | F23: 5 de Abril | G23: NY | H23: Majors | I23: EURUSD | J23: ICT | K23: 1m | L23: Long | M23: L | Q23: =AL22 -> 10050.864 | R23: =IF(Q23="","",S23*Q23/100%) -> 100.50864 | S23: 0.01 | U23: 1.08 | V23: 1.0791 | W23: =IF(V23="","",IF(L23="Long",U23-V23,V23-U23)) -> 0.0009 | X23: =IF(W23="","",R23) -> 100.50864 | Y23: 1.08414 | Z23: =IF(Y23="","",IF(L23="Long",Y23-U23,U23-Y23)) -> 0.00414 | AA23: =IF(AB23="","",AB23*X23/1) -> 462.33973 | AB23: =IF(Z23="","",Z23*1/W23) -> 4.6 | AC23: 5 de Abril | AD23: 1.07995 | AE23: -3.7 | AF23: 0 | AG23: -6.16 | AH23: =IF(AG23="","",AG23+AF23+AE23) -> -9.86 | AI23: =IF(AD23="","",IF(L23="Long",AD23-U23,U23-AD23)) -> -5e-05 | AJ23: =IF(AI23="","",AG23*S23/X23) -> -0.00061288265 | AK23: =IF(AI23="","",(AG23+AF23+AE23)*S23/X23) -> -0.00098101022 | AL23: =Q23+AH23 -> 10041.004 | AV23: 1m | BH23: CHFJPY | BI23: =$BA$11 -> Minors | BL23: A | BM23: Take Profit no ponto definido inicialmente - saida automática
B24: FTMO challenge 1 | C24: 90 | D24: 15 | E24: 3ª F | F24: 9 de Abril | G24: NY | H24: Majors | I24: AUDUSD | J24: ICT | K24: 1m | L24: Short | M24: L | Q24: =AL23 -> 10041.004 | R24: =IF(Q24="","",S24*Q24/100%) -> 100.41004 | S24: 0.01 | U24: 0.66183 | V24: 0.662 | W24: =IF(V24="","",IF(L24="Long",U24-V24,V24-U24)) -> 0.00017 | X24: =IF(W24="","",R24) -> 100.41004 | Y24: 0.66114 | Z24: =IF(Y24="","",IF(L24="Long",Y24-U24,U24-Y24)) -> 0.00069 | AA24: =IF(AB24="","",AB24*X24/1) -> 407.54662 | AB24: =IF(Z24="","",Z24*1/W24) -> 4.0588235 | AC24: 9 de Abril | AD24: =V24 -> 0.662 | AE24: -11.24 | AF24: 0 | AG24: =-X24 -> -100.41004 | AH24: =IF(AG24="","",AG24+AF24+AE24) -> -111.65004 | AI24: =IF(AD24="","",IF(L24="Long",AD24-U24,U24-AD24)) -> -0.00017 | AJ24: =IF(AI24="","",AG24*S24/X24) -> -0.01 | AK24: =IF(AI24="","",(AG24+AF24+AE24)*S24/X24) -> -0.01111941 | AL24: =Q24+AH24 -> 9929.3536 | AV24: 2m | BH24: EURAUD | BI24: =$BA$11 -> Minors | BL24: B | BM24: Stop-Win em trailing Sop com estratégia
B25: FTMO challenge 1 | C25: 91 | D25: 15 | E25: 3ª F | F25: 9 de Abril | G25: NY | H25: Majors | I25: EURUSD | J25: ICT | K25: 1m | L25: long | M25: W | Q25: =AL24 -> 9929.3536 | R25: =IF(Q25="","",S25*Q25/100%) -> 99.293536 | S25: 0.01 | U25: 1.08668 | V25: 1.08594 | W25: =IF(V25="","",IF(L25="Long",U25-V25,V25-U25)) -> 0.00074 | X25: =IF(W25="","",R25) -> 99.293536 | Y25: 1.08901 | Z25: =IF(Y25="","",IF(L25="Long",Y25-U25,U25-Y25)) -> 0.00233 | AA25: =IF(AB25="","",AB25*X25/1) -> 312.64046 | AB25: =IF(Z25="","",Z25*1/W25) -> 3.1486486 | AC25: 9 de Abril | AD25: 1.08594 | AE25: -4.2 | AF25: 0 | AG25: 176.04 | AH25: =IF(AG25="","",AG25+AF25+AE25) -> 171.84 | AI25: =IF(AD25="","",IF(L25="Long",AD25-U25,U25-AD25)) -> -0.00074 | AJ25: =IF(AI25="","",AG25*S25/X25) -> 0.017729251 | AK25: =IF(AI25="","",(AG25+AF25+AE25)*S25/X25) -> 0.017306262 | AL25: =Q25+AH25 -> 10101.194 | AV25: 4m | BH25: EURCAD | BI25: =$BA$11 -> Minors | BL25: C | BM25: Stop-Loss Parcial devido a falha na posição - Reversão da posição a negativo - Stop de Segurança
B26: FTMO challenge 1 | C26: 92 | D26: 15 | E26: 4ª F | F26: 10 de Abril | G26: NY | H26: Majors | I26: EURUSD | J26: ICT | K26: 1m | L26: Short | M26: L | Q26: =AL25 -> 10101.194 | R26: =IF(Q26="","",S26*Q26/100%) -> 101.01194 | S26: 0.01 | U26: 1.08594 | V26: 1.08635 | W26: =IF(V26="","",IF(L26="Long",U26-V26,V26-U26)) -> 0.00041 | X26: =IF(W26="","",R26) -> 101.01194 | Y26: 1.08491 | Z26: =IF(Y26="","",IF(L26="Long",Y26-U26,U26-Y26)) -> 0.00103 | AA26: =IF(AB26="","",AB26*X26/1) -> 253.76169 | AB26: =IF(Z26="","",Z26*1/W26) -> 2.5121951 | AC26: 10 de Abril | AD26: 1.08601 | AE26: -7.74 | AF26: 0 | AG26: -18.05 | AH26: =IF(AG26="","",AG26+AF26+AE26) -> -25.79 | AI26: =IF(AD26="","",IF(L26="Long",AD26-U26,U26-AD26)) -> -7e-05 | AJ26: =IF(AI26="","",AG26*S26/X26) -> -0.0017869175 | AK26: =IF(AI26="","",(AG26+AF26+AE26)*S26/X26) -> -0.0025531636 | AL26: =Q26+AH26 -> 10075.404 | BH26: EURCHF | BI26: =$BA$11 -> Minors | BL26: D | BM26: Stop-Loss Total - Má gestão de saída da posição
B27: FTMO challenge 1 | C27: 93 | D27: 15 | E27: 4ª F | F27: 10 de Abril | G27: NY | H27: Majors | I27: EURUSD | J27: ICT | K27: 1m | L27: Short | M27: L | Q27: =AL26 -> 10075.404 | R27: =IF(Q27="","",S27*Q27/100%) -> 100.75404 | S27: 0.01 | U27: 1.08594 | V27: 1.08633 | W27: =IF(V27="","",IF(L27="Long",U27-V27,V27-U27)) -> 0.00039 | X27: =IF(W27="","",R27) -> 100.75404 | Y27: 1.08491 | Z27: =IF(Y27="","",IF(L27="Long",Y27-U27,U27-Y27)) -> 0.00103 | AA27: =IF(AB27="","",AB27*X27/1) -> 266.09399 | AB27: =IF(Z27="","",Z27*1/W27) -> 2.6410256 | AC27: 10 de Abril | AD27: 1.08619 | AE27: -8.56 | AF27: 0 | AG27: -71.35 | AH27: =IF(AG27="","",AG27+AF27+AE27) -> -79.91 | AI27: =IF(AD27="","",IF(L27="Long",AD27-U27,U27-AD27)) -> -0.00025 | AJ27: =IF(AI27="","",AG27*S27/X27) -> -0.0070816021 | AK27: =IF(AI27="","",(AG27+AF27+AE27)*S27/X27) -> -0.0079311959 | AL27: =Q27+AH27 -> 9995.4936 | BH27: EURGBP | BI27: =$BA$11 -> Minors | BL27: E | BM27: Fecho Manual - Desconforto com a posição/ 1ª Vela negativa / Reversão
B28: FTMO challenge 1 | C28: 94 | D28: 15 | E28: 4ª F | F28: 10 de Abril | G28: NY | H28: Majors | I28: EURUSD | J28: ICT | K28: 1m | L28: Long | M28: L | Q28: =AL27 -> 9995.4936 | R28: =IF(Q28="","",S28*Q28/100%) -> 99.954936 | S28: 0.01 | U28: 1.07546 | V28: 1.07489 | W28: =IF(V28="","",IF(L28="Long",U28-V28,V28-U28)) -> 0.00057 | X28: =IF(W28="","",R28) -> 99.954936 | Y28: 1.07785 | Z28: =IF(Y28="","",IF(L28="Long",Y28-U28,U28-Y28)) -> 0.00239 | AA28: =IF(AB28="","",AB28*X28/1) -> 419.10929 | AB28: =IF(Z28="","",Z28*1/W28) -> 4.1929825 | AC28: 10 de Abril | AD28: 1.07546 | AE28: -5.6 | AF28: 0 | AG28: -60.4 | AH28: =IF(AG28="","",AG28+AF28+AE28) -> -66 | AI28: =IF(AD28="","",IF(L28="Long",AD28-U28,U28-AD28)) -> 0 | AJ28: =IF(AI28="","",AG28*S28/X28) -> -0.0060427231 | AK28: =IF(AI28="","",(AG28+AF28+AE28)*S28/X28) -> -0.0066029755 | AL28: =Q28+AH28 -> 9929.4936 | BH28: EURJPY | BI28: =$BA$11 -> Minors
B29: FTMO challenge 1 | C29: 100 | D29: 19 | E29: 2ª F | F29: 6 de Maio | G29: Londres | H29: Majors | I29: GBPUSD | J29: ICT | K29: 1m | L29: Short | M29: W | Q29: =AL28 -> 9929.4936 | R29: =IF(Q29="","",S29*Q29/100%) -> 99.294936 | S29: 0.01 | U29: 1.25713 | V29: 1.25753 | W29: =IF(V29="","",IF(L29="Long",U29-V29,V29-U29)) -> 0.0004 | X29: =IF(W29="","",R29) -> 99.294936 | Y29: 1.25673 | Z29: =IF(Y29="","",IF(L29="Long",Y29-U29,U29-Y29)) -> 0.0004 | AA29: =IF(AB29="","",AB29*X29/1) -> 99.294936 | AB29: =IF(Z29="","",Z29*1/W29) -> 1 | AC29: 6 de Maio | AD29: =Y29 -> 1.25673 | AE29: -7.08 | AF29: 0 | AG29: =AA29 -> 99.294936 | AH29: =IF(AG29="","",AG29+AF29+AE29) -> 92.214936 | AI29: =IF(AD29="","",IF(L29="Long",AD29-U29,U29-AD29)) -> 0.0004 | AJ29: =IF(AI29="","",AG29*S29/X29) -> 0.01 | AK29: =IF(AI29="","",(AG29+AF29+AE29)*S29/X29) -> 0.0092869727 | AL29: =Q29+AH29 -> 10021.709 | BH29: EURNZD | BI29: =$BA$11 -> Minors
B30: FTMO challenge 1 | C30: 101 | D30: 19 | E30: 3ª F | F30: 7 de Maio | G30: Londres | H30: Majors | I30: GBPUSD | J30: ICT | K30: 1m | L30: Short | M30: W | Q30: =AL29 -> 10021.709 | R30: =IF(Q30="","",S30*Q30/100%) -> 100.21709 | S30: 0.01 | U30: 1.25427 | V30: 1.25477 | W30: =IF(V30="","",IF(L30="Long",U30-V30,V30-U30)) -> 0.0005 | X30: =IF(W30="","",R30) -> 100.21709 | Y30: 1.25376 | Z30: =IF(Y30="","",IF(L30="Long",Y30-U30,U30-Y30)) -> 0.00051 | AA30: =IF(AB30="","",AB30*X30/1) -> 102.22143 | AB30: =IF(Z30="","",Z30*1/W30) -> 1.02 | AC30: 7 de Maio | AD30: =Y30 -> 1.25376 | AE30: -6.54 | AF30: 0 | AG30: =AA30 -> 102.22143 | AH30: =IF(AG30="","",AG30+AF30+AE30) -> 95.681428 | AI30: =IF(AD30="","",IF(L30="Long",AD30-U30,U30-AD30)) -> 0.00051 | AJ30: =IF(AI30="","",AG30*S30/X30) -> 0.0102 | AK30: =IF(AI30="","",(AG30+AF30+AE30)*S30/X30) -> 0.0095474167 | AL30: =Q30+AH30 -> 10117.39 | BH30: GBPAUD | BI30: =$BA$11 -> Minors
B31: FTMO challenge 1 | C31: 102 | D31: 19 | E31: 3ª F | F31: 7 de Maio | G31: NY | H31: Majors | I31: EURUSD | J31: ICT | K31: 1m | L31: Short | M31: L | Q31: =AL30 -> 10117.39 | R31: =IF(Q31="","",S31*Q31/100%) -> 101.1739 | S31: 0.01 | U31: 1.07753 | V31: 1.07789 | W31: =IF(V31="","",IF(L31="Long",U31-V31,V31-U31)) -> 0.00036 | X31: =IF(W31="","",R31) -> 101.1739 | Y31: 1.07717 | Z31: =IF(Y31="","",IF(L31="Long",Y31-U31,U31-Y31)) -> 0.00036 | AA31: =IF(AB31="","",AB31*X31/1) -> 101.1739 | AB31: =IF(Z31="","",Z31*1/W31) -> 1 | AC31: 7 de Maio | AD31: =V31 -> 1.07789 | AE31: -8.82 | AF31: 0 | AG31: =-X31 -> -101.1739 | AH31: =IF(AG31="","",AG31+AF31+AE31) -> -109.9939 | AI31: =IF(AD31="","",IF(L31="Long",AD31-U31,U31-AD31)) -> -0.00036 | AJ31: =IF(AI31="","",AG31*S31/X31) -> -0.01 | AK31: =IF(AI31="","",(AG31+AF31+AE31)*S31/X31) -> -0.010871766 | AL31: =Q31+AH31 -> 10007.396 | BH31: GBPCAD | BI31: =$BA$11 -> Minors
B32: FTMO challenge 1 | C32: 103 | D32: 19 | E32: 4ª F | F32: 8 de Maio | G32: NY | H32: Majors | I32: GBPUSD | J32: ICT | K32: 1m | L32: Long | M32: L | Q32: =AL31 -> 10007.396 | R32: =IF(Q32="","",S32*Q32/100%) -> 100.07396 | S32: 0.01 | U32: 1.24788 | V32: 1.24741 | W32: =IF(V32="","",IF(L32="Long",U32-V32,V32-U32)) -> 0.00047 | X32: =IF(W32="","",R32) -> 100.07396 | Y32: 1.24842 | Z32: =IF(Y32="","",IF(L32="Long",Y32-U32,U32-Y32)) -> 0.00054 | AA32: =IF(AB32="","",AB32*X32/1) -> 114.97859 | AB32: =IF(Z32="","",Z32*1/W32) -> 1.1489362 | AC32: 8 de Maio | AD32: 1.24842 | AE32: -6.68 | AF32: 0 | AG32: =-X32 -> -100.07396 | AH32: =IF(AG32="","",AG32+AF32+AE32) -> -106.75396 | AI32: =IF(AD32="","",IF(L32="Long",AD32-U32,U32-AD32)) -> 0.00054 | AJ32: =IF(AI32="","",AG32*S32/X32) -> -0.01 | AK32: =IF(AI32="","",(AG32+AF32+AE32)*S32/X32) -> -0.010667506 | AL32: =Q32+AH32 -> 9900.6421 | BH32: GBPCHF | BI32: =$BA$11 -> Minors
B33: FTMO challenge 1 | C33: 104 | D33: 19 | E33: 5ª F | F33: 9 de Maio | G33: Londres | H33: Majors | I33: GBPUSD | J33: ICT | K33: 1m | L33: Long | M33: L | Q33: =AL32 -> 9900.6421 | R33: =IF(Q33="","",S33*Q33/100%) -> 99.006421 | S33: 0.01 | U33: 1.24774 | V33: 1.24729 | W33: =IF(V33="","",IF(L33="Long",U33-V33,V33-U33)) -> 0.00045 | X33: =IF(W33="","",R33) -> 99.006421 | Y33: 1.24819 | Z33: =IF(Y33="","",IF(L33="Long",Y33-U33,U33-Y33)) -> 0.00045 | AA33: =IF(AB33="","",AB33*X33/1) -> 99.006421 | AB33: =IF(Z33="","",Z33*1/W33) -> 1 | AC33: 9 de Maio | AD33: 1.24748 | AE33: -6.96 | AF33: 0 | AG33: =-X33 -> -99.006421 | AH33: =IF(AG33="","",AG33+AF33+AE33) -> -105.96642 | AI33: =IF(AD33="","",IF(L33="Long",AD33-U33,U33-AD33)) -> -0.00026 | AJ33: =IF(AI33="","",AG33*S33/X33) -> -0.01 | AK33: =IF(AI33="","",(AG33+AF33+AE33)*S33/X33) -> -0.010702985 | AL33: =Q33+AH33 -> 9794.6757 | BH33: GBPJPY | BI33: =$BA$11 -> Minors
B34: FTMO challenge 1 | C34: 105 | D34: 20 | E34: 2ª F | F34: 13 de Maio | G34: Londres | H34: Majors | I34: GBPUSD | J34: ICT | K34: 5m | L34: Short | M34: L | Q34: =AL33 -> 9794.6757 | R34: =IF(Q34="","",S34*Q34/100%) -> 97.946757 | S34: 0.01 | U34: 1.25241 | V34: 1.25282 | W34: =IF(V34="","",IF(L34="Long",U34-V34,V34-U34)) -> 0.00041 | X34: =IF(W34="","",R34) -> 97.946757 | Y34: 1.252 | Z34: =IF(Y34="","",IF(L34="Long",Y34-U34,U34-Y34)) -> 0.00041 | AA34: =IF(AB34="","",AB34*X34/1) -> 97.946757 | AB34: =IF(Z34="","",Z34*1/W34) -> 1 | AC34: 13 de Maio | AD34: =V34 -> 1.25282 | AE34: -7.4 | AF34: 0 | AG34: =-X34 -> -97.946757 | AH34: =IF(AG34="","",AG34+AF34+AE34) -> -105.34676 | AI34: =IF(AD34="","",IF(L34="Long",AD34-U34,U34-AD34)) -> -0.00041 | AJ34: =IF(AI34="","",AG34*S34/X34) -> -0.01 | AK34: =IF(AI34="","",(AG34+AF34+AE34)*S34/X34) -> -0.010755513 | AL34: =Q34+AH34 -> 9689.329 | BH34: GBPNZD | BI34: =$BA$11 -> Minors
B35: FTMO challenge 1 | C35: 106 | D35: 20 | E35: 2ª F | F35: 13 de Maio | G35: NY | H35: Majors | I35: GBPUSD | J35: ICT | K35: 5m | L35: Short | M35: L | Q35: =AL34 -> 9689.329 | R35: =IF(Q35="","",S35*Q35/100%) -> 96.89329 | S35: 0.01 | U35: 1.25591 | V35: 1.25647 | W35: =IF(V35="","",IF(L35="Long",U35-V35,V35-U35)) -> 0.00056 | X35: =IF(W35="","",R35) -> 96.89329 | Y35: 1.25535 | Z35: =IF(Y35="","",IF(L35="Long",Y35-U35,U35-Y35)) -> 0.00056 | AA35: =IF(AB35="","",AB35*X35/1) -> 96.89329 | AB35: =IF(Z35="","",Z35*1/W35) -> 1 | AC35: 13 de Maio | AD35: =V35 -> 1.25647 | AE35: -5.61 | AF35: 0 | AG35: =-X35 -> -96.89329 | AH35: =IF(AG35="","",AG35+AF35+AE35) -> -102.50329 | AI35: =IF(AD35="","",IF(L35="Long",AD35-U35,U35-AD35)) -> -0.00056 | AJ35: =IF(AI35="","",AG35*S35/X35) -> -0.01 | AK35: =IF(AI35="","",(AG35+AF35+AE35)*S35/X35) -> -0.010578987 | AL35: =Q35+AH35 -> 9586.8257 | BH35: NZDCAD | BI35: =$BA$11 -> Minors
B36: FTMO challenge 1 | C36: 107 | D36: 21 | E36: 2ª F | F36: 20 de Maio | G36: NY | H36: Majors | I36: EURUSD | J36: ICT | K36: 1m | L36: Long | M36: W | Q36: =AL35 -> 9586.8257 | R36: =IF(Q36="","",S36*Q36/100%) -> 95.868257 | S36: 0.01 | U36: 1.08593 | V36: 1.08556 | W36: =IF(V36="","",IF(L36="Long",U36-V36,V36-U36)) -> 0.00037 | X36: =IF(W36="","",R36) -> 95.868257 | Y36: 1.08655 | Z36: =IF(Y36="","",IF(L36="Long",Y36-U36,U36-Y36)) -> 0.00062 | AA36: =IF(AB36="","",AB36*X36/1) -> 160.64411 | AB36: =IF(Z36="","",Z36*1/W36) -> 1.6756757 | AC36: 20 de Maio | AD36: =Y36 -> 1.08655 | AE36: -8.23 | AF36: 0 | AG36: =AA36 -> 160.64411 | AH36: =IF(AG36="","",AG36+AF36+AE36) -> 152.41411 | AI36: =IF(AD36="","",IF(L36="Long",AD36-U36,U36-AD36)) -> 0.00062 | AJ36: =IF(AI36="","",AG36*S36/X36) -> 0.016756757 | AK36: =IF(AI36="","",(AG36+AF36+AE36)*S36/X36) -> 0.015898287 | AL36: =Q36+AH36 -> 9739.2398 | BH36: NZDCHF | BI36: =$BA$11 -> Minors
B37: FTMO challenge 1 | C37: 108 | D37: 22 | E37: 2ª F | F37: 27 de Maio | G37: NY | H37: Majors | I37: EURUSD | J37: SSL | K37: 1m | L37: Long | M37: w | Q37: =AL36 -> 9739.2398 | R37: =IF(Q37="","",S37*Q37/100%) -> 97.392398 | S37: 0.01 | U37: 1.0847 | V37: 1.08432 | W37: =IF(V37="","",IF(L37="Long",U37-V37,V37-U37)) -> 0.00038 | X37: =IF(W37="","",R37) -> 97.392398 | Y37: 1.08564 | Z37: =IF(Y37="","",IF(L37="Long",Y37-U37,U37-Y37)) -> 0.00094 | AA37: =IF(AB37="","",AB37*X37/1) -> 240.91804 | AB37: =IF(Z37="","",Z37*1/W37) -> 2.4736842 | AC37: 27 de Maio | AD37: 1.08496 | AE37: -8.1 | AF37: 0 | AG37: 57 | AH37: =IF(AG37="","",AG37+AF37+AE37) -> 48.9 | AI37: =IF(AD37="","",IF(L37="Long",AD37-U37,U37-AD37)) -> 0.00026 | AJ37: =IF(AI37="","",AG37*S37/X37) -> 0.0058526129 | AK37: =IF(AI37="","",(AG37+AF37+AE37)*S37/X37) -> 0.0050209258 | AL37: =Q37+AH37 -> 9788.1398 | BH37: NZDJPY | BI37: =$BA$11 -> Minors
B38: FTMO challenge 1 | C38: 109 | D38: 22 | E38: 5ª F | F38: 30 de Maio | G38: Londres | H38: Majors | I38: AUDUSD | J38: BSL | K38: 1m | L38: Short | M38: W | Q38: =AL37 -> 9788.1398 | R38: =IF(Q38="","",S38*Q38/100%) -> 97.881398 | S38: 0.01 | U38: 0.66083 | V38: 0.66112 | W38: =IF(V38="","",IF(L38="Long",U38-V38,V38-U38)) -> 0.00029 | X38: =IF(W38="","",R38) -> 97.881398 | Y38: 0.66053 | Z38: =IF(Y38="","",IF(L38="Long",Y38-U38,U38-Y38)) -> 0.0003 | AA38: =IF(AB38="","",AB38*X38/1) -> 101.25662 | AB38: =IF(Z38="","",Z38*1/W38) -> 1.0344828 | AC38: 30 de Maio | AD38: =Y38 -> 0.66053 | AE38: -9.1 | AF38: 0 | AG38: =X38 -> 97.881398 | AH38: =IF(AG38="","",AG38+AF38+AE38) -> 88.781398 | AI38: =IF(AD38="","",IF(L38="Long",AD38-U38,U38-AD38)) -> 0.0003 | AJ38: =IF(AI38="","",AG38*S38/X38) -> 0.01 | AK38: =IF(AI38="","",(AG38+AF38+AE38)*S38/X38) -> 0.0090703034 | AL38: =Q38+AH38 -> 9876.9212 | BH38: NZDUSD | BI38: =$BA$11 -> Minors
B39: FTMO challenge 1 | C39: 110 | D39: 23 | E39: 2ª F | F39: 3 de Junho | G39: Londres | H39: Majors | I39: GBPUSD | J39: SSL | K39: 1m | L39: Long | M39: L | Q39: =AL38 -> 9876.9212 | R39: =IF(Q39="","",S39*Q39/100%) -> 98.769212 | S39: 0.01 | U39: 1.27367 | V39: 1.27325 | W39: =IF(V39="","",IF(L39="Long",U39-V39,V39-U39)) -> 0.00042 | X39: =IF(W39="","",R39) -> 98.769212 | Y39: 1.27409 | Z39: =IF(Y39="","",IF(L39="Long",Y39-U39,U39-Y39)) -> 0.00042 | AA39: =IF(AB39="","",AB39*X39/1) -> 98.769212 | AB39: =IF(Z39="","",Z39*1/W39) -> 1 | AC39: 3 de Junho | AD39: 1.27352 | AE39: -7.08 | AF39: 0 | AG39: -61.32 | AH39: =IF(AG39="","",AG39+AF39+AE39) -> -68.4 | AI39: =IF(AD39="","",IF(L39="Long",AD39-U39,U39-AD39)) -> -0.00015 | AJ39: =IF(AI39="","",AG39*S39/X39) -> -0.0062084124 | AK39: =IF(AI39="","",(AG39+AF39+AE39)*S39/X39) -> -0.006925235 | AL39: =Q39+AH39 -> 9808.5212 | BH39: USDSGD | BI39: =$BA$11 -> Minors
B40: FTMO challenge 1 | C40: 111 | D40: 23 | E40: 2ª F | F40: 3 de Junho | G40: Londres | H40: Majors | I40: USDCAD | J40: BSL | K40: 1m | L40: Short | M40: L | Q40: =AL39 -> 9808.5212 | R40: =IF(Q40="","",S40*Q40/100%) -> 98.085212 | S40: 0.01 | U40: 1.36523 | V40: 1.36571 | W40: =IF(V40="","",IF(L40="Long",U40-V40,V40-U40)) -> 0.00048 | X40: =IF(W40="","",R40) -> 98.085212 | Y40: 1.36463 | Z40: =IF(Y40="","",IF(L40="Long",Y40-U40,U40-Y40)) -> 0.0006 | AA40: =IF(AB40="","",AB40*X40/1) -> 122.60651 | AB40: =IF(Z40="","",Z40*1/W40) -> 1.25 | AC40: 3 de Junho | AD40: =V40 -> 1.36571 | AE40: -8.82 | AF40: 0 | AG40: =-X40 -> -98.085212 | AH40: =IF(AG40="","",AG40+AF40+AE40) -> -106.90521 | AI40: =IF(AD40="","",IF(L40="Long",AD40-U40,U40-AD40)) -> -0.00048 | AJ40: =IF(AI40="","",AG40*S40/X40) -> -0.01 | AK40: =IF(AI40="","",(AG40+AF40+AE40)*S40/X40) -> -0.010899218 | AL40: =Q40+AH40 -> 9701.616 | BH40: AUDSGD | BI40: =$BA$12 -> Exotics
B41: FTMO challenge 1 | C41: 112 | D41: 23 | E41: 2ª F | F41: 3 de Junho | G41: Londres | H41: Majors | I41: USDCAD | J41: BSL | K41: 1m | L41: Short | Q41: =AL40 -> 9701.616 | R41: =IF(Q41="","",S41*Q41/100%) -> 97.01616 | S41: 0.01 | U41: 1.36546 | V41: 1.366 | W41: =IF(V41="","",IF(L41="Long",U41-V41,V41-U41)) -> 0.00054 | X41: =IF(W41="","",R41) -> 97.01616 | Y41: 1.36463 | Z41: =IF(Y41="","",IF(L41="Long",Y41-U41,U41-Y41)) -> 0.00083 | AA41: =IF(AB41="","",AB41*X41/1) -> 149.11743 | AB41: =IF(Z41="","",Z41*1/W41) -> 1.537037 | AC41: 3 de Junho | AD41: =U41 -> 1.36546 | AE41: -7.9 | AF41: 0 | AG41: 0 | AH41: =IF(AG41="","",AG41+AF41+AE41) -> -7.9 | AI41: =IF(AD41="","",IF(L41="Long",AD41-U41,U41-AD41)) -> 0 | AJ41: =IF(AI41="","",AG41*S41/X41) -> 0 | AK41: =IF(AI41="","",(AG41+AF41+AE41)*S41/X41) -> -0.00081429733 | AL41: =Q41+AH41 -> 9693.716 | BH41: CHFSGD | BI41: =$BA$12 -> Exotics
B42: FTMO challenge 1 | C42: 113 | D42: 23 | E42: 3ª F | F42: 4 de Junho | G42: Londres | H42: Majors | I42: AUDUSD | J42: SSL | K42: 1m | L42: Long | M42: L | Q42: =AL41 -> 9693.716 | R42: =IF(Q42="","",S42*Q42/100%) -> 96.93716 | S42: 0.01 | U42: 0.66637 | V42: 0.66602 | W42: =IF(V42="","",IF(L42="Long",U42-V42,V42-U42)) -> 0.00035 | X42: =IF(W42="","",R42) -> 96.93716 | Y42: 0.66707 | Z42: =IF(Y42="","",IF(L42="Long",Y42-U42,U42-Y42)) -> 0.0007 | AA42: =IF(AB42="","",AB42*X42/1) -> 193.87432 | AB42: =IF(Z42="","",Z42*1/W42) -> 2 | AC42: 4 de Junho | AD42: =V42 -> 0.66602 | AE42: -9.01 | AF42: 0 | AG42: =-X42 -> -96.93716 | AH42: =IF(AG42="","",AG42+AF42+AE42) -> -105.94716 | AI42: =IF(AD42="","",IF(L42="Long",AD42-U42,U42-AD42)) -> -0.00035 | AJ42: =IF(AI42="","",AG42*S42/X42) -> -0.01 | AK42: =IF(AI42="","",(AG42+AF42+AE42)*S42/X42) -> -0.010929468 | AL42: =Q42+AH42 -> 9587.7688 | BH42: EURDKK | BI42: =$BA$12 -> Exotics
...

Sheet Statistics
A3: Nº Entradas/Dia semana | B3: 2ª Feira | C3: 3ª Feira | D3: 4ª Feira | E3: 5ª Feira | F3: 6ª Feira
B4: =COUNTIF('Registo de operações'!$E$11:$E$1001,'Registo de operações'!AS10) -> 22 | C4: =COUNTIF('Registo de operações'!$E$11:$E$211,'Registo de operações'!AS11) -> 15 | D4: =COUNTIF('Registo de operações'!$E$11:$E$211,'Registo de operações'!AS12) -> 17 | E4: =COUNTIF('Registo de operações'!$E$11:$E$211,'Registo de operações'!AS13) -> 18 | F4: =COUNTIF('Registo de operações'!$E$11:$E$211,'Registo de operações'!AS14) -> 9
A5: Acerto: | B5: =COUNTIFS('Registo de operações'!$E$11:$E$1001,'Registo de operações'!$AS$10,'Registo de operações'!$M$11:$M$1001,'Registo de operações'!$AW$10) -> 8 | C5: =COUNTIFS('Registo de operações'!$E$11:$E$1001,'Registo de operações'!$AS$11,'Registo de operações'!$M$11:$M$1001,'Registo de operações'!$AW$10) -> 9 | D5: =COUNTIFS('Registo de operações'!$E$11:$E$1001,'Registo de operações'!$AS$12,'Registo de operações'!$M$11:$M$1001,'Registo de operações'!$AW$10) -> 4 | E5: =COUNTIFS('Registo de operações'!$E$11:$E$1001,'Registo de operações'!$AS$13,'Registo de operações'!$M$11:$M$1001,'Registo de operações'!$AW$10) -> 5 | F5: =COUNTIFS('Registo de operações'!$E$11:$E$1001,'Registo de operações'!$AS$14,'Registo de operações'!$M$11:$M$1001,'Registo de operações'!$AW$10) -> 1
A6: Perda: | B6: =COUNTIFS('Registo de operações'!$E$11:$E$1001,'Registo de operações'!$AS$10,'Registo de operações'!$M$11:$M$1001,'Registo de operações'!$AW$11) -> 10 | C6: =COUNTIFS('Registo de operações'!$E$11:$E$1001,'Registo de operações'!$AS$11,'Registo de operações'!$M$11:$M$1001,'Registo de operações'!$AW$11) -> 6 | D6: =COUNTIFS('Registo de operações'!$E$11:$E$1001,'Registo de operações'!$AS$12,'Registo de operações'!$M$11:$M$1001,'Registo de operações'!$AW$11) -> 12 | E6: =COUNTIFS('Registo de operações'!$E$11:$E$1001,'Registo de operações'!$AS$13,'Registo de operações'!$M$11:$M$1001,'Registo de operações'!$AW$11) -> 12 | F6: =COUNTIFS('Registo de operações'!$E$11:$E$1001,'Registo de operações'!$AS$14,'Registo de operações'!$M$11:$M$1001,'Registo de operações'!$AW$11) -> 7
A7: Taxa de Acerto: | B7: =B5/B4 -> 0.36363636 | C7: =C5/C4 -> 0.6 | D7: =D5/D4 -> 0.23529412 | E7: =E5/E4 -> 0.27777778 | F7: =F5/F4 -> 0.11111111
A8: Manhã
A9: Tarde
A12: Marcos Temporais | B12: 3 Minutos | C12: 5 Minutos | D12: 15 Minutos | E12: 30 Minutos | F12: 1 Hora | G12: 2 Horas | H12: 4 Horas | I12: 8 Horas | J12: 1 Dia | K12: 1 Semana
B13: =COUNTIF('Registo de operações'!$K$11:$K$211,'Registo de operações'!AV19) -> 7 | C13: =COUNTIF('Registo de operações'!$K$11:$K$211,'Registo de operações'!$AV$18) -> 5 | D13: =COUNTIF('Registo de operações'!$K$11:$K$211,'Registo de operações'!$AV$17) -> 1 | E13: =COUNTIF('Registo de operações'!$K$11:$K$211,'Registo de operações'!$AV$16) -> 1 | F13: =COUNTIF('Registo de operações'!$K$11:$K$211,'Registo de operações'!$AV$15) -> 0 | G13: =COUNTIF('Registo de operações'!$K$11:$K$211,'Registo de operações'!$AV$14) -> 0 | H13: =COUNTIF('Registo de operações'!$K$11:$K$211,'Registo de operações'!$AV$13) -> 0 | I13: =COUNTIF('Registo de operações'!$K$11:$K$211,'Registo de operações'!$AV$12) -> 0 | J13: =COUNTIF('Registo de operações'!$K$11:$K$211,'Registo de operações'!$AV$10) -> 0 | K13: =COUNTIF('Registo de operações'!$K$11:$K$211,'Registo de operações'!$AV$20) -> 0
A14: Acerto: | B14: =COUNTIFS('Registo de operações'!$K$11:$K$1001,'Registo de operações'!$AV$19,'Registo de operações'!$M$11:$M$1001,'Registo de operações'!$AW$10) -> 3 | C14: =COUNTIFS('Registo de operações'!$K$11:$K$1001,'Registo de operações'!$AV$18,'Registo de operações'!$M$11:$M$1001,'Registo de operações'!$AW$10) -> 1 | D14: =COUNTIFS('Registo de operações'!$K$11:$K$1001,'Registo de operações'!$AV$17,'Registo de operações'!$M$11:$M$1001,'Registo de operações'!$AW$10) -> 0 | E14: =COUNTIFS('Registo de operações'!$K$11:$K$1001,'Registo de operações'!$AV$16,'Registo de operações'!$M$11:$M$1001,'Registo de operações'!$AW$10) -> 0 | F14: =COUNTIFS('Registo de operações'!$K$11:$K$1001,'Registo de operações'!$AV$15,'Registo de operações'!$M$11:$M$1001,'Registo de operações'!$AW$10) -> 0 | G14: =COUNTIFS('Registo de operações'!$K$11:$K$1001,'Registo de operações'!$AV$14,'Registo de operações'!$M$11:$M$1001,'Registo de operações'!$AW$10) -> 0 | H14: =COUNTIFS('Registo de operações'!$K$11:$K$1001,'Registo de operações'!$AV$13,'Registo de operações'!$M$11:$M$1001,'Registo de operações'!$AW$10) -> 0 | I14: =COUNTIFS('Registo de operações'!$K$11:$K$1001,'Registo de operações'!$AV$12,'Registo de operações'!$M$11:$M$1001,'Registo de operações'!$AW$10) -> 0 | J14: =COUNTIFS('Registo de operações'!$K$11:$K$1001,'Registo de operações'!$AV$10,'Registo de operações'!$M$11:$M$1001,'Registo de operações'!$AW$10) -> 0 | K14: =COUNTIFS('Registo de operações'!$K$11:$K$1001,'Registo de operações'!$AV$20,'Registo de operações'!$M$11:$M$1001,'Registo de operações'!$AW$10) -> 0
A15: Perda: | B15: =COUNTIFS('Registo de operações'!$K$11:$K$1001,'Registo de operações'!$AV$19,'Registo de operações'!$M$11:$M$1001,'Registo de operações'!$AW$11) -> 3 | C15: =COUNTIFS('Registo de operações'!$K$11:$K$1001,'Registo de operações'!$AV$18,'Registo de operações'!$M$11:$M$1001,'Registo de operações'!$AW$11) -> 4 | D15: =COUNTIFS('Registo de operações'!$K$11:$K$1001,'Registo de operações'!$AV$17,'Registo de operações'!$M$11:$M$1001,'Registo de operações'!$AW$11) -> 0 | E15: =COUNTIFS('Registo de operações'!$K$11:$K$1001,'Registo de operações'!$AV$16,'Registo de operações'!$M$11:$M$1001,'Registo de operações'!$AW$11) -> 1 | F15: =COUNTIFS('Registo de operações'!$K$11:$K$1001,'Registo de operações'!$AV$15,'Registo de operações'!$M$11:$M$1001,'Registo de operações'!$AW$11) -> 0 | G15: =COUNTIFS('Registo de operações'!$K$11:$K$1001,'Registo de operações'!$AV$14,'Registo de operações'!$M$11:$M$1001,'Registo de operações'!$AW$11) -> 0 | H15: =COUNTIFS('Registo de operações'!$K$11:$K$1001,'Registo de operações'!$AV$13,'Registo de operações'!$M$11:$M$1001,'Registo de operações'!$AW$11) -> 0 | I15: =COUNTIFS('Registo de operações'!$K$11:$K$1001,'Registo de operações'!$AV$12,'Registo de operações'!$M$11:$M$1001,'Registo de operações'!$AW$11) -> 0 | J15: =COUNTIFS('Registo de operações'!$K$11:$K$1001,'Registo de operações'!$AV$10,'Registo de operações'!$M$11:$M$1001,'Registo de operações'!$AW$11) -> 0 | K15: =COUNTIFS('Registo de operações'!$K$11:$K$1001,'Registo de operações'!$AV$20,'Registo de operações'!$M$11:$M$1001,'Registo de operações'!$AW$11) -> 0
A16: Taxa de Acerto: | B16: =B14/B13 -> 0.42857143 | C16: =C14/C13 -> 0.2 | D16: =D14/D13 -> 0 | E16: =E14/E13 -> 0 | F16: =F14/F13 -> #DIV/0! | G16: =G14/G13 -> #DIV/0! | H16: =H14/H13 -> #DIV/0! | I16: =I14/I13 -> #DIV/0! | ... K16: =K14/K13 -> #DIV/0!
A17: Estratégia
A18: Breakout
A19: Bandeira
A20: Retest
A22: Entradas por estratégia | B22: BreakOut | C22: Bandeira | D22: Retest | E22: Total
B23: =COUNTIF('Registo de operações'!$J$11:$J$1001,'Registo de operações'!AU11) -> 25 | C23: =COUNTIF('Registo de operações'!$J$11:$J$1001,'Registo de operações'!AU12) -> 2 | D23: =COUNTIF('Registo de operações'!$J$11:$J$1001,'Registo de operações'!AU10) -> 26 | E23: =SUM(B23:D23) -> 53
A24: Acerto: | B24: =COUNTIFS('Registo de operações'!$J$11:$J$1001,'Registo de operações'!$AU$11,'Registo de operações'!$M$11:$M$1001,'Registo de operações'!AW10) -> 8 | C24: =COUNTIFS('Registo de operações'!$J$11:$J$1001,'Registo de operações'!$AU$12,'Registo de operações'!$M$11:$M$1001,'Registo de operações'!AW10) -> 1 | D24: =COUNTIFS('Registo de operações'!$J$11:$J$1001,'Registo de operações'!$AU$10,'Registo de operações'!$M$11:$M$1001,'Registo de operações'!AW10) -> 10
A25: Perda: | B25: =COUNTIFS('Registo de operações'!$J$11:$J$1001,'Registo de operações'!$AU$11,'Registo de operações'!$M$11:$M$1001,'Registo de operações'!AW11) -> 15 | C25: =COUNTIFS('Registo de operações'!$J$11:$J$1001,'Registo de operações'!$AU$12,'Registo de operações'!$M$11:$M$1001,'Registo de operações'!AW11) -> 1 | D25: =COUNTIFS('Registo de operações'!$J$11:$J$1001,'Registo de operações'!$AU$10,'Registo de operações'!$M$11:$M$1001,'Registo de operações'!AW11) -> 13
A26: Taxa de Acerto estratégia: | B26: =B24/B23 -> 0.32 | C26: =C24/C23 -> 0.5 | D26: =D24/D23 -> 0.38461538

Sheet Evolução de Conta

Sheet Pontuação
H1: Majors | I1: Minors | J1: Exotics | K1: Breakout | M1: Retest
B2: =SUM(B5:B204) -> 0.43638742 | C2: =SUM(C5:C204) -> -0.43733417 | D2: =SUM(D5:D204) -> 4242.6641 | E2: =SUM(E5:E204) -> -4302.8764 | G2: W | H2: =COUNTIFS(#REF!,"Majors",$L$11:$L$210,"W") -> #REF! | I2: =COUNTIFS(#REF!,"Minors",$L$11:$L$210,"W") -> #REF! | J2: =COUNTIFS(#REF!,"Exotics",$L$11:$L$210,"W") -> #REF! | K2: 6 | L2: =K2*100%/#REF! -> #REF! | M2: 11 | N2: =M2*100%/$C$5 -> -1100
B3: =AVERAGE(B5:B204) -> 0.014546247 | C3: =AVERAGE(C5:C204) -> -0.0089251872 | D3: =AVERAGE(D5:D204) -> 141.42214 | E3: =AVERAGE(E5:E204) -> -87.813803 | G3: L | H3: =H4-H2 -> #REF! | I3: =I4-I2 -> #REF! | J3: =J4-J2 -> #REF! | K3: 7 | L3: =K3*100%/#REF! -> #REF! | M3: 14 | N3: =M3*100%/$C$5 -> -1400
A4: Nº T | B4: Ganhos % | C4: Perdas % | D4: Ganhos € | E4: Perdas € | G4: Total | H4: =COUNTIF(#REF!,"MAJORS") -> #REF! | I4: =COUNTIF(#REF!,"minors") -> #REF! | J4: =COUNTIF(#REF!,"Exotics") -> #REF! | K4: =SUM(K2:K3) -> 13 | L4: =SUM(L2:L3) -> #REF! | M4: =SUM(M2:M3) -> 25 | N4: =SUM(N2:N3) -> -2500
A5: ='Registo de operações'!C11 -> 77 | B5: =IF('Registo de operações'!AJ11>0,'Registo de operações'!AJ11,"") | C5: =IF('Registo de operações'!AJ11<0,'Registo de operações'!AJ11,"") -> -0.01 | D5: =IF('Registo de operações'!AG11>0,'Registo de operações'!AG11,"") | E5: =IF('Registo de operações'!AG11<0,'Registo de operações'!AG11,"") -> -100
A6: ='Registo de operações'!C12 -> 78 | B6: =IF('Registo de operações'!AJ12>0,'Registo de operações'!AJ12,"") | C6: =IF('Registo de operações'!AJ12<0,'Registo de operações'!AJ12,"") -> -0.01 | D6: =IF('Registo de operações'!AG12>0,'Registo de operações'!AG12,"") | E6: =IF('Registo de operações'!AG12<0,'Registo de operações'!AG12,"") -> -98.987
A7: ='Registo de operações'!C13 -> 79 | B7: =IF('Registo de operações'!AJ13>0,'Registo de operações'!AJ13,"") | C7: =IF('Registo de operações'!AJ13<0,'Registo de operações'!AJ13,"") -> -0.01 | D7: =IF('Registo de operações'!AG13>0,'Registo de operações'!AG13,"") | E7: =IF('Registo de operações'!AG13<0,'Registo de operações'!AG13,"") -> -97.85733
A8: ='Registo de operações'!C14 -> 80 | B8: =IF('Registo de operações'!AJ14>0,'Registo de operações'!AJ14,"") | C8: =IF('Registo de operações'!AJ14<0,'Registo de operações'!AJ14,"") -> -0.01 | D8: =IF('Registo de operações'!AG14>0,'Registo de operações'!AG14,"") | E8: =IF('Registo de operações'!AG14<0,'Registo de operações'!AG14,"") -> -96.692357
A9: ='Registo de operações'!C15 -> 81 | B9: =IF('Registo de operações'!AJ15>0,'Registo de operações'!AJ15,"") -> 0.024285714 | C9: =IF('Registo de operações'!AJ15<0,'Registo de operações'!AJ15,"") | D9: =IF('Registo de operações'!AG15>0,'Registo de operações'!AG15,"") -> 231.93788 | E9: =IF('Registo de operações'!AG15<0,'Registo de operações'!AG15,"")
A10: ='Registo de operações'!C16 -> 82 | B10: =IF('Registo de operações'!AJ16>0,'Registo de operações'!AJ16,"") -> 0.029 | C10: =IF('Registo de operações'!AJ16<0,'Registo de operações'!AJ16,"") | D10: =IF('Registo de operações'!AG16>0,'Registo de operações'!AG16,"") -> 283.29262 | E10: =IF('Registo de operações'!AG16<0,'Registo de operações'!AG16,"")
A11: ='Registo de operações'!C17 -> 83 | B11: =IF('Registo de operações'!AJ17>0,'Registo de operações'!AJ17,"") -> 0.016228039 | C11: =IF('Registo de operações'!AJ17<0,'Registo de operações'!AJ17,"") | D11: =IF('Registo de operações'!AG17>0,'Registo de operações'!AG17,"") -> 163 | E11: =IF('Registo de operações'!AG17<0,'Registo de operações'!AG17,"")
A12: ='Registo de operações'!C18 -> 84 | B12: =IF('Registo de operações'!AJ18>0,'Registo de operações'!AJ18,"") | C12: =IF('Registo de operações'!AJ18<0,'Registo de operações'!AJ18,"") -> -0.01 | D12: =IF('Registo de operações'!AG18>0,'Registo de operações'!AG18,"") | E12: =IF('Registo de operações'!AG18<0,'Registo de operações'!AG18,"") -> -102.00014
A13: ='Registo de operações'!C19 -> 85 | B13: =IF('Registo de operações'!AJ19>0,'Registo de operações'!AJ19,"") -> 0.006953396 | C13: =IF('Registo de operações'!AJ19<0,'Registo de operações'!AJ19,"") | D13: =IF('Registo de operações'!AG19>0,'Registo de operações'!AG19,"") -> 70.16 | E13: =IF('Registo de operações'!AG19<0,'Registo de operações'!AG19,"")
A14: ='Registo de operações'!C20 -> 86 | B14: =IF('Registo de operações'!AJ20>0,'Registo de operações'!AJ20,"") | C14: =IF('Registo de operações'!AJ20<0,'Registo de operações'!AJ20,"") -> -0.0019882413 | D14: =IF('Registo de operações'!AG20>0,'Registo de operações'!AG20,"") | E14: =IF('Registo de operações'!AG20<0,'Registo de operações'!AG20,"") -> -20.18
A15: ='Registo de operações'!C21 -> 87 | B15: =IF('Registo de operações'!AJ21>0,'Registo de operações'!AJ21,"") | C15: =IF('Registo de operações'!AJ21<0,'Registo de operações'!AJ21,"") | D15: =IF('Registo de operações'!AG21>0,'Registo de operações'!AG21,"") | E15: =IF('Registo de operações'!AG21<0,'Registo de operações'!AG21,"")
A16: ='Registo de operações'!C22 -> 88 | B16: =IF('Registo de operações'!AJ22>0,'Registo de operações'!AJ22,"") | C16: =IF('Registo de operações'!AJ22<0,'Registo de operações'!AJ22,"") -> -0.0052185516 | D16: =IF('Registo de operações'!AG22>0,'Registo de operações'!AG22,"") | E16: =IF('Registo de operações'!AG22<0,'Registo de operações'!AG22,"") -> -52.79
... A203: ='Registo de operações'!C209 -> 0 | B203: =IF('Registo de operações'!AJ209>0,'Registo de operações'!AJ209,"") | C203: =IF('Registo de operações'!AJ209<0,'Registo de operações'!AJ209,"") | D203: =IF('Registo de operações'!AG209>0,'Registo de operações'!AG209,"") | E203: =IF('Registo de operações'!AG209<0,'Registo de operações'!AG209,"")
A204: ='Registo de operações'!C211 -> 0 | B204: =IF('Registo de operações'!AJ211>0,'Registo de operações'!AJ211,"") | C204: =IF('Registo de operações'!AJ211<0,'Registo de operações'!AJ211,"") | D204: =IF('Registo de operações'!AG211>0,'Registo de operações'!AG211,"") | E204: =IF('Registo de operações'!AG211<0,'Registo de operações'!AG211,"")
